2025-09-03 18:20:28,253 - INFO - Iniciando carga de datos desde 'data\departments.csv' a la tabla 'departments'...
2025-09-03 18:20:28,253 - ERROR - Error: El archivo no se encontró en la ruta 'data\departments.csv'
2025-09-03 18:20:28,254 - INFO - Iniciando carga de datos desde 'data\jobs.csv' a la tabla 'jobs'...
2025-09-03 18:20:28,254 - ERROR - Error: El archivo no se encontró en la ruta 'data\jobs.csv'
2025-09-03 18:20:28,255 - INFO - Iniciando carga de datos desde 'data\hired_employees.csv' a la tabla 'hired_employees'...
2025-09-03 18:20:28,255 - ERROR - Error: El archivo no se encontró en la ruta 'data\hired_employees.csv'
2025-09-03 18:21:50,036 - INFO - Iniciando carga de datos desde 'data\departments.csv' a la tabla 'departments'...
2025-09-03 18:21:50,037 - ERROR - Error: El archivo no se encontró en la ruta 'data\departments.csv'
2025-09-03 18:21:50,038 - INFO - Iniciando carga de datos desde 'data\jobs.csv' a la tabla 'jobs'...
2025-09-03 18:21:50,038 - ERROR - Error: El archivo no se encontró en la ruta 'data\jobs.csv'
2025-09-03 18:21:50,038 - INFO - Iniciando carga de datos desde 'data\hired_employees.csv' a la tabla 'hired_employees'...
2025-09-03 18:21:50,039 - ERROR - Error: El archivo no se encontró en la ruta 'data\hired_employees.csv'
2025-09-03 18:28:03,149 - INFO - Iniciando carga de datos desde 'data\departments.csv' a la tabla 'departments'...
2025-09-03 18:28:19,752 - ERROR - Error fatal durante la carga de datos en 'departments': (pyodbc.OperationalError) ('08001', '[08001] [Microsoft][ODBC Driver 17 for SQL Server]Named Pipes Provider: Could not open a connection to SQL Server [53].  (53) (SQLDriverConnect); [08001] [Microsoft][ODBC Driver 17 for SQL Server]Login timeout expired (0); [08001] [Microsoft][ODBC Driver 17 for SQL Server]A network-related or instance-specific error has occurred while establishing a connection to SQL Server. Server is not found or not accessible. Check if instance name is correct and if SQL Server is configured to allow remote connections. For more information see SQL Server Books Online. (53)')
(Background on this error at: https://sqlalche.me/e/20/e3q8)
Traceback (most recent call last):
  File "C:\Users\User\Desktop\Pruebas_Lab\Prueba_Jikk\.venv\Lib\site-packages\sqlalchemy\engine\base.py", line 143, in __init__
    self._dbapi_connection = engine.raw_connection()
                             ~~~~~~~~~~~~~~~~~~~~~^^
  File "C:\Users\User\Desktop\Pruebas_Lab\Prueba_Jikk\.venv\Lib\site-packages\sqlalchemy\engine\base.py", line 3301, in raw_connection
    return self.pool.connect()
           ~~~~~~~~~~~~~~~~~^^
  File "C:\Users\User\Desktop\Pruebas_Lab\Prueba_Jikk\.venv\Lib\site-packages\sqlalchemy\pool\base.py", line 447, in connect
    return _ConnectionFairy._checkout(self)
           ~~~~~~~~~~~~~~~~~~~~~~~~~~^^^^^^
  File "C:\Users\User\Desktop\Pruebas_Lab\Prueba_Jikk\.venv\Lib\site-packages\sqlalchemy\pool\base.py", line 1264, in _checkout
    fairy = _ConnectionRecord.checkout(pool)
  File "C:\Users\User\Desktop\Pruebas_Lab\Prueba_Jikk\.venv\Lib\site-packages\sqlalchemy\pool\base.py", line 711, in checkout
    rec = pool._do_get()
  File "C:\Users\User\Desktop\Pruebas_Lab\Prueba_Jikk\.venv\Lib\site-packages\sqlalchemy\pool\impl.py", line 177, in _do_get
    with util.safe_reraise():
         ~~~~~~~~~~~~~~~~~^^
  File "C:\Users\User\Desktop\Pruebas_Lab\Prueba_Jikk\.venv\Lib\site-packages\sqlalchemy\util\langhelpers.py", line 224, in __exit__
    raise exc_value.with_traceback(exc_tb)
  File "C:\Users\User\Desktop\Pruebas_Lab\Prueba_Jikk\.venv\Lib\site-packages\sqlalchemy\pool\impl.py", line 175, in _do_get
    return self._create_connection()
           ~~~~~~~~~~~~~~~~~~~~~~~^^
  File "C:\Users\User\Desktop\Pruebas_Lab\Prueba_Jikk\.venv\Lib\site-packages\sqlalchemy\pool\base.py", line 388, in _create_connection
    return _ConnectionRecord(self)
  File "C:\Users\User\Desktop\Pruebas_Lab\Prueba_Jikk\.venv\Lib\site-packages\sqlalchemy\pool\base.py", line 673, in __init__
    self.__connect()
    ~~~~~~~~~~~~~~^^
  File "C:\Users\User\Desktop\Pruebas_Lab\Prueba_Jikk\.venv\Lib\site-packages\sqlalchemy\pool\base.py", line 899, in __connect
    with util.safe_reraise():
         ~~~~~~~~~~~~~~~~~^^
  File "C:\Users\User\Desktop\Pruebas_Lab\Prueba_Jikk\.venv\Lib\site-packages\sqlalchemy\util\langhelpers.py", line 224, in __exit__
    raise exc_value.with_traceback(exc_tb)
  File "C:\Users\User\Desktop\Pruebas_Lab\Prueba_Jikk\.venv\Lib\site-packages\sqlalchemy\pool\base.py", line 895, in __connect
    self.dbapi_connection = connection = pool._invoke_creator(self)
                                         ~~~~~~~~~~~~~~~~~~~~^^^^^^
  File "C:\Users\User\Desktop\Pruebas_Lab\Prueba_Jikk\.venv\Lib\site-packages\sqlalchemy\engine\create.py", line 661, in connect
    return dialect.connect(*cargs, **cparams)
           ~~~~~~~~~~~~~~~^^^^^^^^^^^^^^^^^^^
  File "C:\Users\User\Desktop\Pruebas_Lab\Prueba_Jikk\.venv\Lib\site-packages\sqlalchemy\engine\default.py", line 629, in connect
    return self.loaded_dbapi.connect(*cargs, **cparams)  # type: ignore[no-any-return]  # NOQA: E501
           ~~~~~~~~~~~~~~~~~~~~~~~~~^^^^^^^^^^^^^^^^^^^
pyodbc.OperationalError: ('08001', '[08001] [Microsoft][ODBC Driver 17 for SQL Server]Named Pipes Provider: Could not open a connection to SQL Server [53].  (53) (SQLDriverConnect); [08001] [Microsoft][ODBC Driver 17 for SQL Server]Login timeout expired (0); [08001] [Microsoft][ODBC Driver 17 for SQL Server]A network-related or instance-specific error has occurred while establishing a connection to SQL Server. Server is not found or not accessible. Check if instance name is correct and if SQL Server is configured to allow remote connections. For more information see SQL Server Books Online. (53)')

The above exception was the direct cause of the following exception:

Traceback (most recent call last):
  File "c:\Users\User\Desktop\Pruebas_Lab\Prueba_Jikk\historico.py", line 38, in load_data_from_csv
    chunk.to_sql(table_name, con=engine, if_exists='append', index=False)
    ~~~~~~~~~~~~^^^^^^^^^^^^^^^^^^^^^^^^^^^^^^^^^^^^^^^^^^^^^^^^^^^^^^^^^
  File "C:\Users\User\Desktop\Pruebas_Lab\Prueba_Jikk\.venv\Lib\site-packages\pandas\util\_decorators.py", line 333, in wrapper
    return func(*args, **kwargs)
  File "C:\Users\User\Desktop\Pruebas_Lab\Prueba_Jikk\.venv\Lib\site-packages\pandas\core\generic.py", line 3106, in to_sql
    return sql.to_sql(
           ~~~~~~~~~~^
        self,
        ^^^^^
    ...<8 lines>...
        method=method,
        ^^^^^^^^^^^^^^
    )
    ^
  File "C:\Users\User\Desktop\Pruebas_Lab\Prueba_Jikk\.venv\Lib\site-packages\pandas\io\sql.py", line 843, in to_sql
    with pandasSQL_builder(con, schema=schema, need_transaction=True) as pandas_sql:
         ~~~~~~~~~~~~~~~~~^^^^^^^^^^^^^^^^^^^^^^^^^^^^^^^^^^^^^^^^^^^
  File "C:\Users\User\Desktop\Pruebas_Lab\Prueba_Jikk\.venv\Lib\site-packages\pandas\io\sql.py", line 908, in pandasSQL_builder
    return SQLDatabase(con, schema, need_transaction)
  File "C:\Users\User\Desktop\Pruebas_Lab\Prueba_Jikk\.venv\Lib\site-packages\pandas\io\sql.py", line 1648, in __init__
    con = self.exit_stack.enter_context(con.connect())
                                        ~~~~~~~~~~~^^
  File "C:\Users\User\Desktop\Pruebas_Lab\Prueba_Jikk\.venv\Lib\site-packages\sqlalchemy\engine\base.py", line 3277, in connect
    return self._connection_cls(self)
           ~~~~~~~~~~~~~~~~~~~~^^^^^^
  File "C:\Users\User\Desktop\Pruebas_Lab\Prueba_Jikk\.venv\Lib\site-packages\sqlalchemy\engine\base.py", line 145, in __init__
    Connection._handle_dbapi_exception_noconnection(
    ~~~~~~~~~~~~~~~~~~~~~~~~~~~~~~~~~~~~~~~~~~~~~~~^
        err, dialect, engine
        ^^^^^^^^^^^^^^^^^^^^
    )
    ^
  File "C:\Users\User\Desktop\Pruebas_Lab\Prueba_Jikk\.venv\Lib\site-packages\sqlalchemy\engine\base.py", line 2440, in _handle_dbapi_exception_noconnection
    raise sqlalchemy_exception.with_traceback(exc_info[2]) from e
  File "C:\Users\User\Desktop\Pruebas_Lab\Prueba_Jikk\.venv\Lib\site-packages\sqlalchemy\engine\base.py", line 143, in __init__
    self._dbapi_connection = engine.raw_connection()
                             ~~~~~~~~~~~~~~~~~~~~~^^
  File "C:\Users\User\Desktop\Pruebas_Lab\Prueba_Jikk\.venv\Lib\site-packages\sqlalchemy\engine\base.py", line 3301, in raw_connection
    return self.pool.connect()
           ~~~~~~~~~~~~~~~~~^^
  File "C:\Users\User\Desktop\Pruebas_Lab\Prueba_Jikk\.venv\Lib\site-packages\sqlalchemy\pool\base.py", line 447, in connect
    return _ConnectionFairy._checkout(self)
           ~~~~~~~~~~~~~~~~~~~~~~~~~~^^^^^^
  File "C:\Users\User\Desktop\Pruebas_Lab\Prueba_Jikk\.venv\Lib\site-packages\sqlalchemy\pool\base.py", line 1264, in _checkout
    fairy = _ConnectionRecord.checkout(pool)
  File "C:\Users\User\Desktop\Pruebas_Lab\Prueba_Jikk\.venv\Lib\site-packages\sqlalchemy\pool\base.py", line 711, in checkout
    rec = pool._do_get()
  File "C:\Users\User\Desktop\Pruebas_Lab\Prueba_Jikk\.venv\Lib\site-packages\sqlalchemy\pool\impl.py", line 177, in _do_get
    with util.safe_reraise():
         ~~~~~~~~~~~~~~~~~^^
  File "C:\Users\User\Desktop\Pruebas_Lab\Prueba_Jikk\.venv\Lib\site-packages\sqlalchemy\util\langhelpers.py", line 224, in __exit__
    raise exc_value.with_traceback(exc_tb)
  File "C:\Users\User\Desktop\Pruebas_Lab\Prueba_Jikk\.venv\Lib\site-packages\sqlalchemy\pool\impl.py", line 175, in _do_get
    return self._create_connection()
           ~~~~~~~~~~~~~~~~~~~~~~~^^
  File "C:\Users\User\Desktop\Pruebas_Lab\Prueba_Jikk\.venv\Lib\site-packages\sqlalchemy\pool\base.py", line 388, in _create_connection
    return _ConnectionRecord(self)
  File "C:\Users\User\Desktop\Pruebas_Lab\Prueba_Jikk\.venv\Lib\site-packages\sqlalchemy\pool\base.py", line 673, in __init__
    self.__connect()
    ~~~~~~~~~~~~~~^^
  File "C:\Users\User\Desktop\Pruebas_Lab\Prueba_Jikk\.venv\Lib\site-packages\sqlalchemy\pool\base.py", line 899, in __connect
    with util.safe_reraise():
         ~~~~~~~~~~~~~~~~~^^
  File "C:\Users\User\Desktop\Pruebas_Lab\Prueba_Jikk\.venv\Lib\site-packages\sqlalchemy\util\langhelpers.py", line 224, in __exit__
    raise exc_value.with_traceback(exc_tb)
  File "C:\Users\User\Desktop\Pruebas_Lab\Prueba_Jikk\.venv\Lib\site-packages\sqlalchemy\pool\base.py", line 895, in __connect
    self.dbapi_connection = connection = pool._invoke_creator(self)
                                         ~~~~~~~~~~~~~~~~~~~~^^^^^^
  File "C:\Users\User\Desktop\Pruebas_Lab\Prueba_Jikk\.venv\Lib\site-packages\sqlalchemy\engine\create.py", line 661, in connect
    return dialect.connect(*cargs, **cparams)
           ~~~~~~~~~~~~~~~^^^^^^^^^^^^^^^^^^^
  File "C:\Users\User\Desktop\Pruebas_Lab\Prueba_Jikk\.venv\Lib\site-packages\sqlalchemy\engine\default.py", line 629, in connect
    return self.loaded_dbapi.connect(*cargs, **cparams)  # type: ignore[no-any-return]  # NOQA: E501
           ~~~~~~~~~~~~~~~~~~~~~~~~~^^^^^^^^^^^^^^^^^^^
sqlalchemy.exc.OperationalError: (pyodbc.OperationalError) ('08001', '[08001] [Microsoft][ODBC Driver 17 for SQL Server]Named Pipes Provider: Could not open a connection to SQL Server [53].  (53) (SQLDriverConnect); [08001] [Microsoft][ODBC Driver 17 for SQL Server]Login timeout expired (0); [08001] [Microsoft][ODBC Driver 17 for SQL Server]A network-related or instance-specific error has occurred while establishing a connection to SQL Server. Server is not found or not accessible. Check if instance name is correct and if SQL Server is configured to allow remote connections. For more information see SQL Server Books Online. (53)')
(Background on this error at: https://sqlalche.me/e/20/e3q8)
2025-09-03 18:28:19,785 - INFO - Iniciando carga de datos desde 'data\jobs.csv' a la tabla 'jobs'...
2025-09-03 18:28:36,957 - ERROR - Error fatal durante la carga de datos en 'jobs': (pyodbc.OperationalError) ('08001', '[08001] [Microsoft][ODBC Driver 17 for SQL Server]Named Pipes Provider: Could not open a connection to SQL Server [53].  (53) (SQLDriverConnect); [08001] [Microsoft][ODBC Driver 17 for SQL Server]Login timeout expired (0); [08001] [Microsoft][ODBC Driver 17 for SQL Server]A network-related or instance-specific error has occurred while establishing a connection to SQL Server. Server is not found or not accessible. Check if instance name is correct and if SQL Server is configured to allow remote connections. For more information see SQL Server Books Online. (53)')
(Background on this error at: https://sqlalche.me/e/20/e3q8)
Traceback (most recent call last):
  File "C:\Users\User\Desktop\Pruebas_Lab\Prueba_Jikk\.venv\Lib\site-packages\sqlalchemy\engine\base.py", line 143, in __init__
    self._dbapi_connection = engine.raw_connection()
                             ~~~~~~~~~~~~~~~~~~~~~^^
  File "C:\Users\User\Desktop\Pruebas_Lab\Prueba_Jikk\.venv\Lib\site-packages\sqlalchemy\engine\base.py", line 3301, in raw_connection
    return self.pool.connect()
           ~~~~~~~~~~~~~~~~~^^
  File "C:\Users\User\Desktop\Pruebas_Lab\Prueba_Jikk\.venv\Lib\site-packages\sqlalchemy\pool\base.py", line 447, in connect
    return _ConnectionFairy._checkout(self)
           ~~~~~~~~~~~~~~~~~~~~~~~~~~^^^^^^
  File "C:\Users\User\Desktop\Pruebas_Lab\Prueba_Jikk\.venv\Lib\site-packages\sqlalchemy\pool\base.py", line 1264, in _checkout
    fairy = _ConnectionRecord.checkout(pool)
  File "C:\Users\User\Desktop\Pruebas_Lab\Prueba_Jikk\.venv\Lib\site-packages\sqlalchemy\pool\base.py", line 711, in checkout
    rec = pool._do_get()
  File "C:\Users\User\Desktop\Pruebas_Lab\Prueba_Jikk\.venv\Lib\site-packages\sqlalchemy\pool\impl.py", line 177, in _do_get
    with util.safe_reraise():
         ~~~~~~~~~~~~~~~~~^^
  File "C:\Users\User\Desktop\Pruebas_Lab\Prueba_Jikk\.venv\Lib\site-packages\sqlalchemy\util\langhelpers.py", line 224, in __exit__
    raise exc_value.with_traceback(exc_tb)
  File "C:\Users\User\Desktop\Pruebas_Lab\Prueba_Jikk\.venv\Lib\site-packages\sqlalchemy\pool\impl.py", line 175, in _do_get
    return self._create_connection()
           ~~~~~~~~~~~~~~~~~~~~~~~^^
  File "C:\Users\User\Desktop\Pruebas_Lab\Prueba_Jikk\.venv\Lib\site-packages\sqlalchemy\pool\base.py", line 388, in _create_connection
    return _ConnectionRecord(self)
  File "C:\Users\User\Desktop\Pruebas_Lab\Prueba_Jikk\.venv\Lib\site-packages\sqlalchemy\pool\base.py", line 673, in __init__
    self.__connect()
    ~~~~~~~~~~~~~~^^
  File "C:\Users\User\Desktop\Pruebas_Lab\Prueba_Jikk\.venv\Lib\site-packages\sqlalchemy\pool\base.py", line 899, in __connect
    with util.safe_reraise():
         ~~~~~~~~~~~~~~~~~^^
  File "C:\Users\User\Desktop\Pruebas_Lab\Prueba_Jikk\.venv\Lib\site-packages\sqlalchemy\util\langhelpers.py", line 224, in __exit__
    raise exc_value.with_traceback(exc_tb)
  File "C:\Users\User\Desktop\Pruebas_Lab\Prueba_Jikk\.venv\Lib\site-packages\sqlalchemy\pool\base.py", line 895, in __connect
    self.dbapi_connection = connection = pool._invoke_creator(self)
                                         ~~~~~~~~~~~~~~~~~~~~^^^^^^
  File "C:\Users\User\Desktop\Pruebas_Lab\Prueba_Jikk\.venv\Lib\site-packages\sqlalchemy\engine\create.py", line 661, in connect
    return dialect.connect(*cargs, **cparams)
           ~~~~~~~~~~~~~~~^^^^^^^^^^^^^^^^^^^
  File "C:\Users\User\Desktop\Pruebas_Lab\Prueba_Jikk\.venv\Lib\site-packages\sqlalchemy\engine\default.py", line 629, in connect
    return self.loaded_dbapi.connect(*cargs, **cparams)  # type: ignore[no-any-return]  # NOQA: E501
           ~~~~~~~~~~~~~~~~~~~~~~~~~^^^^^^^^^^^^^^^^^^^
pyodbc.OperationalError: ('08001', '[08001] [Microsoft][ODBC Driver 17 for SQL Server]Named Pipes Provider: Could not open a connection to SQL Server [53].  (53) (SQLDriverConnect); [08001] [Microsoft][ODBC Driver 17 for SQL Server]Login timeout expired (0); [08001] [Microsoft][ODBC Driver 17 for SQL Server]A network-related or instance-specific error has occurred while establishing a connection to SQL Server. Server is not found or not accessible. Check if instance name is correct and if SQL Server is configured to allow remote connections. For more information see SQL Server Books Online. (53)')

The above exception was the direct cause of the following exception:

Traceback (most recent call last):
  File "c:\Users\User\Desktop\Pruebas_Lab\Prueba_Jikk\historico.py", line 38, in load_data_from_csv
    chunk.to_sql(table_name, con=engine, if_exists='append', index=False)
    ~~~~~~~~~~~~^^^^^^^^^^^^^^^^^^^^^^^^^^^^^^^^^^^^^^^^^^^^^^^^^^^^^^^^^
  File "C:\Users\User\Desktop\Pruebas_Lab\Prueba_Jikk\.venv\Lib\site-packages\pandas\util\_decorators.py", line 333, in wrapper
    return func(*args, **kwargs)
  File "C:\Users\User\Desktop\Pruebas_Lab\Prueba_Jikk\.venv\Lib\site-packages\pandas\core\generic.py", line 3106, in to_sql
    return sql.to_sql(
           ~~~~~~~~~~^
        self,
        ^^^^^
    ...<8 lines>...
        method=method,
        ^^^^^^^^^^^^^^
    )
    ^
  File "C:\Users\User\Desktop\Pruebas_Lab\Prueba_Jikk\.venv\Lib\site-packages\pandas\io\sql.py", line 843, in to_sql
    with pandasSQL_builder(con, schema=schema, need_transaction=True) as pandas_sql:
         ~~~~~~~~~~~~~~~~~^^^^^^^^^^^^^^^^^^^^^^^^^^^^^^^^^^^^^^^^^^^
  File "C:\Users\User\Desktop\Pruebas_Lab\Prueba_Jikk\.venv\Lib\site-packages\pandas\io\sql.py", line 908, in pandasSQL_builder
    return SQLDatabase(con, schema, need_transaction)
  File "C:\Users\User\Desktop\Pruebas_Lab\Prueba_Jikk\.venv\Lib\site-packages\pandas\io\sql.py", line 1648, in __init__
    con = self.exit_stack.enter_context(con.connect())
                                        ~~~~~~~~~~~^^
  File "C:\Users\User\Desktop\Pruebas_Lab\Prueba_Jikk\.venv\Lib\site-packages\sqlalchemy\engine\base.py", line 3277, in connect
    return self._connection_cls(self)
           ~~~~~~~~~~~~~~~~~~~~^^^^^^
  File "C:\Users\User\Desktop\Pruebas_Lab\Prueba_Jikk\.venv\Lib\site-packages\sqlalchemy\engine\base.py", line 145, in __init__
    Connection._handle_dbapi_exception_noconnection(
    ~~~~~~~~~~~~~~~~~~~~~~~~~~~~~~~~~~~~~~~~~~~~~~~^
        err, dialect, engine
        ^^^^^^^^^^^^^^^^^^^^
    )
    ^
  File "C:\Users\User\Desktop\Pruebas_Lab\Prueba_Jikk\.venv\Lib\site-packages\sqlalchemy\engine\base.py", line 2440, in _handle_dbapi_exception_noconnection
    raise sqlalchemy_exception.with_traceback(exc_info[2]) from e
  File "C:\Users\User\Desktop\Pruebas_Lab\Prueba_Jikk\.venv\Lib\site-packages\sqlalchemy\engine\base.py", line 143, in __init__
    self._dbapi_connection = engine.raw_connection()
                             ~~~~~~~~~~~~~~~~~~~~~^^
  File "C:\Users\User\Desktop\Pruebas_Lab\Prueba_Jikk\.venv\Lib\site-packages\sqlalchemy\engine\base.py", line 3301, in raw_connection
    return self.pool.connect()
           ~~~~~~~~~~~~~~~~~^^
  File "C:\Users\User\Desktop\Pruebas_Lab\Prueba_Jikk\.venv\Lib\site-packages\sqlalchemy\pool\base.py", line 447, in connect
    return _ConnectionFairy._checkout(self)
           ~~~~~~~~~~~~~~~~~~~~~~~~~~^^^^^^
  File "C:\Users\User\Desktop\Pruebas_Lab\Prueba_Jikk\.venv\Lib\site-packages\sqlalchemy\pool\base.py", line 1264, in _checkout
    fairy = _ConnectionRecord.checkout(pool)
  File "C:\Users\User\Desktop\Pruebas_Lab\Prueba_Jikk\.venv\Lib\site-packages\sqlalchemy\pool\base.py", line 711, in checkout
    rec = pool._do_get()
  File "C:\Users\User\Desktop\Pruebas_Lab\Prueba_Jikk\.venv\Lib\site-packages\sqlalchemy\pool\impl.py", line 177, in _do_get
    with util.safe_reraise():
         ~~~~~~~~~~~~~~~~~^^
  File "C:\Users\User\Desktop\Pruebas_Lab\Prueba_Jikk\.venv\Lib\site-packages\sqlalchemy\util\langhelpers.py", line 224, in __exit__
    raise exc_value.with_traceback(exc_tb)
  File "C:\Users\User\Desktop\Pruebas_Lab\Prueba_Jikk\.venv\Lib\site-packages\sqlalchemy\pool\impl.py", line 175, in _do_get
    return self._create_connection()
           ~~~~~~~~~~~~~~~~~~~~~~~^^
  File "C:\Users\User\Desktop\Pruebas_Lab\Prueba_Jikk\.venv\Lib\site-packages\sqlalchemy\pool\base.py", line 388, in _create_connection
    return _ConnectionRecord(self)
  File "C:\Users\User\Desktop\Pruebas_Lab\Prueba_Jikk\.venv\Lib\site-packages\sqlalchemy\pool\base.py", line 673, in __init__
    self.__connect()
    ~~~~~~~~~~~~~~^^
  File "C:\Users\User\Desktop\Pruebas_Lab\Prueba_Jikk\.venv\Lib\site-packages\sqlalchemy\pool\base.py", line 899, in __connect
    with util.safe_reraise():
         ~~~~~~~~~~~~~~~~~^^
  File "C:\Users\User\Desktop\Pruebas_Lab\Prueba_Jikk\.venv\Lib\site-packages\sqlalchemy\util\langhelpers.py", line 224, in __exit__
    raise exc_value.with_traceback(exc_tb)
  File "C:\Users\User\Desktop\Pruebas_Lab\Prueba_Jikk\.venv\Lib\site-packages\sqlalchemy\pool\base.py", line 895, in __connect
    self.dbapi_connection = connection = pool._invoke_creator(self)
                                         ~~~~~~~~~~~~~~~~~~~~^^^^^^
  File "C:\Users\User\Desktop\Pruebas_Lab\Prueba_Jikk\.venv\Lib\site-packages\sqlalchemy\engine\create.py", line 661, in connect
    return dialect.connect(*cargs, **cparams)
           ~~~~~~~~~~~~~~~^^^^^^^^^^^^^^^^^^^
  File "C:\Users\User\Desktop\Pruebas_Lab\Prueba_Jikk\.venv\Lib\site-packages\sqlalchemy\engine\default.py", line 629, in connect
    return self.loaded_dbapi.connect(*cargs, **cparams)  # type: ignore[no-any-return]  # NOQA: E501
           ~~~~~~~~~~~~~~~~~~~~~~~~~^^^^^^^^^^^^^^^^^^^
sqlalchemy.exc.OperationalError: (pyodbc.OperationalError) ('08001', '[08001] [Microsoft][ODBC Driver 17 for SQL Server]Named Pipes Provider: Could not open a connection to SQL Server [53].  (53) (SQLDriverConnect); [08001] [Microsoft][ODBC Driver 17 for SQL Server]Login timeout expired (0); [08001] [Microsoft][ODBC Driver 17 for SQL Server]A network-related or instance-specific error has occurred while establishing a connection to SQL Server. Server is not found or not accessible. Check if instance name is correct and if SQL Server is configured to allow remote connections. For more information see SQL Server Books Online. (53)')
(Background on this error at: https://sqlalche.me/e/20/e3q8)
2025-09-03 18:28:36,968 - INFO - Iniciando carga de datos desde 'data\hired_employees.csv' a la tabla 'hired_employees'...
2025-09-03 18:28:53,156 - ERROR - Error fatal durante la carga de datos en 'hired_employees': (pyodbc.OperationalError) ('08001', '[08001] [Microsoft][ODBC Driver 17 for SQL Server]Named Pipes Provider: Could not open a connection to SQL Server [53].  (53) (SQLDriverConnect); [08001] [Microsoft][ODBC Driver 17 for SQL Server]Login timeout expired (0); [08001] [Microsoft][ODBC Driver 17 for SQL Server]A network-related or instance-specific error has occurred while establishing a connection to SQL Server. Server is not found or not accessible. Check if instance name is correct and if SQL Server is configured to allow remote connections. For more information see SQL Server Books Online. (53)')
(Background on this error at: https://sqlalche.me/e/20/e3q8)
Traceback (most recent call last):
  File "C:\Users\User\Desktop\Pruebas_Lab\Prueba_Jikk\.venv\Lib\site-packages\sqlalchemy\engine\base.py", line 143, in __init__
    self._dbapi_connection = engine.raw_connection()
                             ~~~~~~~~~~~~~~~~~~~~~^^
  File "C:\Users\User\Desktop\Pruebas_Lab\Prueba_Jikk\.venv\Lib\site-packages\sqlalchemy\engine\base.py", line 3301, in raw_connection
    return self.pool.connect()
           ~~~~~~~~~~~~~~~~~^^
  File "C:\Users\User\Desktop\Pruebas_Lab\Prueba_Jikk\.venv\Lib\site-packages\sqlalchemy\pool\base.py", line 447, in connect
    return _ConnectionFairy._checkout(self)
           ~~~~~~~~~~~~~~~~~~~~~~~~~~^^^^^^
  File "C:\Users\User\Desktop\Pruebas_Lab\Prueba_Jikk\.venv\Lib\site-packages\sqlalchemy\pool\base.py", line 1264, in _checkout
    fairy = _ConnectionRecord.checkout(pool)
  File "C:\Users\User\Desktop\Pruebas_Lab\Prueba_Jikk\.venv\Lib\site-packages\sqlalchemy\pool\base.py", line 711, in checkout
    rec = pool._do_get()
  File "C:\Users\User\Desktop\Pruebas_Lab\Prueba_Jikk\.venv\Lib\site-packages\sqlalchemy\pool\impl.py", line 177, in _do_get
    with util.safe_reraise():
         ~~~~~~~~~~~~~~~~~^^
  File "C:\Users\User\Desktop\Pruebas_Lab\Prueba_Jikk\.venv\Lib\site-packages\sqlalchemy\util\langhelpers.py", line 224, in __exit__
    raise exc_value.with_traceback(exc_tb)
  File "C:\Users\User\Desktop\Pruebas_Lab\Prueba_Jikk\.venv\Lib\site-packages\sqlalchemy\pool\impl.py", line 175, in _do_get
    return self._create_connection()
           ~~~~~~~~~~~~~~~~~~~~~~~^^
  File "C:\Users\User\Desktop\Pruebas_Lab\Prueba_Jikk\.venv\Lib\site-packages\sqlalchemy\pool\base.py", line 388, in _create_connection
    return _ConnectionRecord(self)
  File "C:\Users\User\Desktop\Pruebas_Lab\Prueba_Jikk\.venv\Lib\site-packages\sqlalchemy\pool\base.py", line 673, in __init__
    self.__connect()
    ~~~~~~~~~~~~~~^^
  File "C:\Users\User\Desktop\Pruebas_Lab\Prueba_Jikk\.venv\Lib\site-packages\sqlalchemy\pool\base.py", line 899, in __connect
    with util.safe_reraise():
         ~~~~~~~~~~~~~~~~~^^
  File "C:\Users\User\Desktop\Pruebas_Lab\Prueba_Jikk\.venv\Lib\site-packages\sqlalchemy\util\langhelpers.py", line 224, in __exit__
    raise exc_value.with_traceback(exc_tb)
  File "C:\Users\User\Desktop\Pruebas_Lab\Prueba_Jikk\.venv\Lib\site-packages\sqlalchemy\pool\base.py", line 895, in __connect
    self.dbapi_connection = connection = pool._invoke_creator(self)
                                         ~~~~~~~~~~~~~~~~~~~~^^^^^^
  File "C:\Users\User\Desktop\Pruebas_Lab\Prueba_Jikk\.venv\Lib\site-packages\sqlalchemy\engine\create.py", line 661, in connect
    return dialect.connect(*cargs, **cparams)
           ~~~~~~~~~~~~~~~^^^^^^^^^^^^^^^^^^^
  File "C:\Users\User\Desktop\Pruebas_Lab\Prueba_Jikk\.venv\Lib\site-packages\sqlalchemy\engine\default.py", line 629, in connect
    return self.loaded_dbapi.connect(*cargs, **cparams)  # type: ignore[no-any-return]  # NOQA: E501
           ~~~~~~~~~~~~~~~~~~~~~~~~~^^^^^^^^^^^^^^^^^^^
pyodbc.OperationalError: ('08001', '[08001] [Microsoft][ODBC Driver 17 for SQL Server]Named Pipes Provider: Could not open a connection to SQL Server [53].  (53) (SQLDriverConnect); [08001] [Microsoft][ODBC Driver 17 for SQL Server]Login timeout expired (0); [08001] [Microsoft][ODBC Driver 17 for SQL Server]A network-related or instance-specific error has occurred while establishing a connection to SQL Server. Server is not found or not accessible. Check if instance name is correct and if SQL Server is configured to allow remote connections. For more information see SQL Server Books Online. (53)')

The above exception was the direct cause of the following exception:

Traceback (most recent call last):
  File "c:\Users\User\Desktop\Pruebas_Lab\Prueba_Jikk\historico.py", line 38, in load_data_from_csv
    chunk.to_sql(table_name, con=engine, if_exists='append', index=False)
    ~~~~~~~~~~~~^^^^^^^^^^^^^^^^^^^^^^^^^^^^^^^^^^^^^^^^^^^^^^^^^^^^^^^^^
  File "C:\Users\User\Desktop\Pruebas_Lab\Prueba_Jikk\.venv\Lib\site-packages\pandas\util\_decorators.py", line 333, in wrapper
    return func(*args, **kwargs)
  File "C:\Users\User\Desktop\Pruebas_Lab\Prueba_Jikk\.venv\Lib\site-packages\pandas\core\generic.py", line 3106, in to_sql
    return sql.to_sql(
           ~~~~~~~~~~^
        self,
        ^^^^^
    ...<8 lines>...
        method=method,
        ^^^^^^^^^^^^^^
    )
    ^
  File "C:\Users\User\Desktop\Pruebas_Lab\Prueba_Jikk\.venv\Lib\site-packages\pandas\io\sql.py", line 843, in to_sql
    with pandasSQL_builder(con, schema=schema, need_transaction=True) as pandas_sql:
         ~~~~~~~~~~~~~~~~~^^^^^^^^^^^^^^^^^^^^^^^^^^^^^^^^^^^^^^^^^^^
  File "C:\Users\User\Desktop\Pruebas_Lab\Prueba_Jikk\.venv\Lib\site-packages\pandas\io\sql.py", line 908, in pandasSQL_builder
    return SQLDatabase(con, schema, need_transaction)
  File "C:\Users\User\Desktop\Pruebas_Lab\Prueba_Jikk\.venv\Lib\site-packages\pandas\io\sql.py", line 1648, in __init__
    con = self.exit_stack.enter_context(con.connect())
                                        ~~~~~~~~~~~^^
  File "C:\Users\User\Desktop\Pruebas_Lab\Prueba_Jikk\.venv\Lib\site-packages\sqlalchemy\engine\base.py", line 3277, in connect
    return self._connection_cls(self)
           ~~~~~~~~~~~~~~~~~~~~^^^^^^
  File "C:\Users\User\Desktop\Pruebas_Lab\Prueba_Jikk\.venv\Lib\site-packages\sqlalchemy\engine\base.py", line 145, in __init__
    Connection._handle_dbapi_exception_noconnection(
    ~~~~~~~~~~~~~~~~~~~~~~~~~~~~~~~~~~~~~~~~~~~~~~~^
        err, dialect, engine
        ^^^^^^^^^^^^^^^^^^^^
    )
    ^
  File "C:\Users\User\Desktop\Pruebas_Lab\Prueba_Jikk\.venv\Lib\site-packages\sqlalchemy\engine\base.py", line 2440, in _handle_dbapi_exception_noconnection
    raise sqlalchemy_exception.with_traceback(exc_info[2]) from e
  File "C:\Users\User\Desktop\Pruebas_Lab\Prueba_Jikk\.venv\Lib\site-packages\sqlalchemy\engine\base.py", line 143, in __init__
    self._dbapi_connection = engine.raw_connection()
                             ~~~~~~~~~~~~~~~~~~~~~^^
  File "C:\Users\User\Desktop\Pruebas_Lab\Prueba_Jikk\.venv\Lib\site-packages\sqlalchemy\engine\base.py", line 3301, in raw_connection
    return self.pool.connect()
           ~~~~~~~~~~~~~~~~~^^
  File "C:\Users\User\Desktop\Pruebas_Lab\Prueba_Jikk\.venv\Lib\site-packages\sqlalchemy\pool\base.py", line 447, in connect
    return _ConnectionFairy._checkout(self)
           ~~~~~~~~~~~~~~~~~~~~~~~~~~^^^^^^
  File "C:\Users\User\Desktop\Pruebas_Lab\Prueba_Jikk\.venv\Lib\site-packages\sqlalchemy\pool\base.py", line 1264, in _checkout
    fairy = _ConnectionRecord.checkout(pool)
  File "C:\Users\User\Desktop\Pruebas_Lab\Prueba_Jikk\.venv\Lib\site-packages\sqlalchemy\pool\base.py", line 711, in checkout
    rec = pool._do_get()
  File "C:\Users\User\Desktop\Pruebas_Lab\Prueba_Jikk\.venv\Lib\site-packages\sqlalchemy\pool\impl.py", line 177, in _do_get
    with util.safe_reraise():
         ~~~~~~~~~~~~~~~~~^^
  File "C:\Users\User\Desktop\Pruebas_Lab\Prueba_Jikk\.venv\Lib\site-packages\sqlalchemy\util\langhelpers.py", line 224, in __exit__
    raise exc_value.with_traceback(exc_tb)
  File "C:\Users\User\Desktop\Pruebas_Lab\Prueba_Jikk\.venv\Lib\site-packages\sqlalchemy\pool\impl.py", line 175, in _do_get
    return self._create_connection()
           ~~~~~~~~~~~~~~~~~~~~~~~^^
  File "C:\Users\User\Desktop\Pruebas_Lab\Prueba_Jikk\.venv\Lib\site-packages\sqlalchemy\pool\base.py", line 388, in _create_connection
    return _ConnectionRecord(self)
  File "C:\Users\User\Desktop\Pruebas_Lab\Prueba_Jikk\.venv\Lib\site-packages\sqlalchemy\pool\base.py", line 673, in __init__
    self.__connect()
    ~~~~~~~~~~~~~~^^
  File "C:\Users\User\Desktop\Pruebas_Lab\Prueba_Jikk\.venv\Lib\site-packages\sqlalchemy\pool\base.py", line 899, in __connect
    with util.safe_reraise():
         ~~~~~~~~~~~~~~~~~^^
  File "C:\Users\User\Desktop\Pruebas_Lab\Prueba_Jikk\.venv\Lib\site-packages\sqlalchemy\util\langhelpers.py", line 224, in __exit__
    raise exc_value.with_traceback(exc_tb)
  File "C:\Users\User\Desktop\Pruebas_Lab\Prueba_Jikk\.venv\Lib\site-packages\sqlalchemy\pool\base.py", line 895, in __connect
    self.dbapi_connection = connection = pool._invoke_creator(self)
                                         ~~~~~~~~~~~~~~~~~~~~^^^^^^
  File "C:\Users\User\Desktop\Pruebas_Lab\Prueba_Jikk\.venv\Lib\site-packages\sqlalchemy\engine\create.py", line 661, in connect
    return dialect.connect(*cargs, **cparams)
           ~~~~~~~~~~~~~~~^^^^^^^^^^^^^^^^^^^
  File "C:\Users\User\Desktop\Pruebas_Lab\Prueba_Jikk\.venv\Lib\site-packages\sqlalchemy\engine\default.py", line 629, in connect
    return self.loaded_dbapi.connect(*cargs, **cparams)  # type: ignore[no-any-return]  # NOQA: E501
           ~~~~~~~~~~~~~~~~~~~~~~~~~^^^^^^^^^^^^^^^^^^^
sqlalchemy.exc.OperationalError: (pyodbc.OperationalError) ('08001', '[08001] [Microsoft][ODBC Driver 17 for SQL Server]Named Pipes Provider: Could not open a connection to SQL Server [53].  (53) (SQLDriverConnect); [08001] [Microsoft][ODBC Driver 17 for SQL Server]Login timeout expired (0); [08001] [Microsoft][ODBC Driver 17 for SQL Server]A network-related or instance-specific error has occurred while establishing a connection to SQL Server. Server is not found or not accessible. Check if instance name is correct and if SQL Server is configured to allow remote connections. For more information see SQL Server Books Online. (53)')
(Background on this error at: https://sqlalche.me/e/20/e3q8)
2025-09-04 10:01:33,631 - INFO - Iniciando carga de datos desde 'data\departments.csv' a la tabla 'departments'...
2025-09-04 10:01:50,371 - ERROR - Error fatal durante la carga de datos en 'departments': (pyodbc.OperationalError) ('08001', '[08001] [Microsoft][ODBC Driver 17 for SQL Server]Named Pipes Provider: Could not open a connection to SQL Server [53].  (53) (SQLDriverConnect); [08001] [Microsoft][ODBC Driver 17 for SQL Server]Login timeout expired (0); [08001] [Microsoft][ODBC Driver 17 for SQL Server]A network-related or instance-specific error has occurred while establishing a connection to SQL Server. Server is not found or not accessible. Check if instance name is correct and if SQL Server is configured to allow remote connections. For more information see SQL Server Books Online. (53)')
(Background on this error at: https://sqlalche.me/e/20/e3q8)
Traceback (most recent call last):
  File "C:\Users\User\Desktop\Pruebas_Lab\Prueba_Jikk\.venv\Lib\site-packages\sqlalchemy\engine\base.py", line 143, in __init__
    self._dbapi_connection = engine.raw_connection()
                             ~~~~~~~~~~~~~~~~~~~~~^^
  File "C:\Users\User\Desktop\Pruebas_Lab\Prueba_Jikk\.venv\Lib\site-packages\sqlalchemy\engine\base.py", line 3301, in raw_connection
    return self.pool.connect()
           ~~~~~~~~~~~~~~~~~^^
  File "C:\Users\User\Desktop\Pruebas_Lab\Prueba_Jikk\.venv\Lib\site-packages\sqlalchemy\pool\base.py", line 447, in connect
    return _ConnectionFairy._checkout(self)
           ~~~~~~~~~~~~~~~~~~~~~~~~~~^^^^^^
  File "C:\Users\User\Desktop\Pruebas_Lab\Prueba_Jikk\.venv\Lib\site-packages\sqlalchemy\pool\base.py", line 1264, in _checkout
    fairy = _ConnectionRecord.checkout(pool)
  File "C:\Users\User\Desktop\Pruebas_Lab\Prueba_Jikk\.venv\Lib\site-packages\sqlalchemy\pool\base.py", line 711, in checkout
    rec = pool._do_get()
  File "C:\Users\User\Desktop\Pruebas_Lab\Prueba_Jikk\.venv\Lib\site-packages\sqlalchemy\pool\impl.py", line 177, in _do_get
    with util.safe_reraise():
         ~~~~~~~~~~~~~~~~~^^
  File "C:\Users\User\Desktop\Pruebas_Lab\Prueba_Jikk\.venv\Lib\site-packages\sqlalchemy\util\langhelpers.py", line 224, in __exit__
    raise exc_value.with_traceback(exc_tb)
  File "C:\Users\User\Desktop\Pruebas_Lab\Prueba_Jikk\.venv\Lib\site-packages\sqlalchemy\pool\impl.py", line 175, in _do_get
    return self._create_connection()
           ~~~~~~~~~~~~~~~~~~~~~~~^^
  File "C:\Users\User\Desktop\Pruebas_Lab\Prueba_Jikk\.venv\Lib\site-packages\sqlalchemy\pool\base.py", line 388, in _create_connection
    return _ConnectionRecord(self)
  File "C:\Users\User\Desktop\Pruebas_Lab\Prueba_Jikk\.venv\Lib\site-packages\sqlalchemy\pool\base.py", line 673, in __init__
    self.__connect()
    ~~~~~~~~~~~~~~^^
  File "C:\Users\User\Desktop\Pruebas_Lab\Prueba_Jikk\.venv\Lib\site-packages\sqlalchemy\pool\base.py", line 899, in __connect
    with util.safe_reraise():
         ~~~~~~~~~~~~~~~~~^^
  File "C:\Users\User\Desktop\Pruebas_Lab\Prueba_Jikk\.venv\Lib\site-packages\sqlalchemy\util\langhelpers.py", line 224, in __exit__
    raise exc_value.with_traceback(exc_tb)
  File "C:\Users\User\Desktop\Pruebas_Lab\Prueba_Jikk\.venv\Lib\site-packages\sqlalchemy\pool\base.py", line 895, in __connect
    self.dbapi_connection = connection = pool._invoke_creator(self)
                                         ~~~~~~~~~~~~~~~~~~~~^^^^^^
  File "C:\Users\User\Desktop\Pruebas_Lab\Prueba_Jikk\.venv\Lib\site-packages\sqlalchemy\engine\create.py", line 661, in connect
    return dialect.connect(*cargs, **cparams)
           ~~~~~~~~~~~~~~~^^^^^^^^^^^^^^^^^^^
  File "C:\Users\User\Desktop\Pruebas_Lab\Prueba_Jikk\.venv\Lib\site-packages\sqlalchemy\engine\default.py", line 629, in connect
    return self.loaded_dbapi.connect(*cargs, **cparams)  # type: ignore[no-any-return]  # NOQA: E501
           ~~~~~~~~~~~~~~~~~~~~~~~~~^^^^^^^^^^^^^^^^^^^
pyodbc.OperationalError: ('08001', '[08001] [Microsoft][ODBC Driver 17 for SQL Server]Named Pipes Provider: Could not open a connection to SQL Server [53].  (53) (SQLDriverConnect); [08001] [Microsoft][ODBC Driver 17 for SQL Server]Login timeout expired (0); [08001] [Microsoft][ODBC Driver 17 for SQL Server]A network-related or instance-specific error has occurred while establishing a connection to SQL Server. Server is not found or not accessible. Check if instance name is correct and if SQL Server is configured to allow remote connections. For more information see SQL Server Books Online. (53)')

The above exception was the direct cause of the following exception:

Traceback (most recent call last):
  File "c:\Users\User\Desktop\Pruebas_Lab\Prueba_Jikk\historico.py", line 38, in load_data_from_csv
    chunk.to_sql(table_name, con=engine, if_exists='append', index=False)
    ~~~~~~~~~~~~^^^^^^^^^^^^^^^^^^^^^^^^^^^^^^^^^^^^^^^^^^^^^^^^^^^^^^^^^
  File "C:\Users\User\Desktop\Pruebas_Lab\Prueba_Jikk\.venv\Lib\site-packages\pandas\util\_decorators.py", line 333, in wrapper
    return func(*args, **kwargs)
  File "C:\Users\User\Desktop\Pruebas_Lab\Prueba_Jikk\.venv\Lib\site-packages\pandas\core\generic.py", line 3106, in to_sql
    return sql.to_sql(
           ~~~~~~~~~~^
        self,
        ^^^^^
    ...<8 lines>...
        method=method,
        ^^^^^^^^^^^^^^
    )
    ^
  File "C:\Users\User\Desktop\Pruebas_Lab\Prueba_Jikk\.venv\Lib\site-packages\pandas\io\sql.py", line 843, in to_sql
    with pandasSQL_builder(con, schema=schema, need_transaction=True) as pandas_sql:
         ~~~~~~~~~~~~~~~~~^^^^^^^^^^^^^^^^^^^^^^^^^^^^^^^^^^^^^^^^^^^
  File "C:\Users\User\Desktop\Pruebas_Lab\Prueba_Jikk\.venv\Lib\site-packages\pandas\io\sql.py", line 908, in pandasSQL_builder
    return SQLDatabase(con, schema, need_transaction)
  File "C:\Users\User\Desktop\Pruebas_Lab\Prueba_Jikk\.venv\Lib\site-packages\pandas\io\sql.py", line 1648, in __init__
    con = self.exit_stack.enter_context(con.connect())
                                        ~~~~~~~~~~~^^
  File "C:\Users\User\Desktop\Pruebas_Lab\Prueba_Jikk\.venv\Lib\site-packages\sqlalchemy\engine\base.py", line 3277, in connect
    return self._connection_cls(self)
           ~~~~~~~~~~~~~~~~~~~~^^^^^^
  File "C:\Users\User\Desktop\Pruebas_Lab\Prueba_Jikk\.venv\Lib\site-packages\sqlalchemy\engine\base.py", line 145, in __init__
    Connection._handle_dbapi_exception_noconnection(
    ~~~~~~~~~~~~~~~~~~~~~~~~~~~~~~~~~~~~~~~~~~~~~~~^
        err, dialect, engine
        ^^^^^^^^^^^^^^^^^^^^
    )
    ^
  File "C:\Users\User\Desktop\Pruebas_Lab\Prueba_Jikk\.venv\Lib\site-packages\sqlalchemy\engine\base.py", line 2440, in _handle_dbapi_exception_noconnection
    raise sqlalchemy_exception.with_traceback(exc_info[2]) from e
  File "C:\Users\User\Desktop\Pruebas_Lab\Prueba_Jikk\.venv\Lib\site-packages\sqlalchemy\engine\base.py", line 143, in __init__
    self._dbapi_connection = engine.raw_connection()
                             ~~~~~~~~~~~~~~~~~~~~~^^
  File "C:\Users\User\Desktop\Pruebas_Lab\Prueba_Jikk\.venv\Lib\site-packages\sqlalchemy\engine\base.py", line 3301, in raw_connection
    return self.pool.connect()
           ~~~~~~~~~~~~~~~~~^^
  File "C:\Users\User\Desktop\Pruebas_Lab\Prueba_Jikk\.venv\Lib\site-packages\sqlalchemy\pool\base.py", line 447, in connect
    return _ConnectionFairy._checkout(self)
           ~~~~~~~~~~~~~~~~~~~~~~~~~~^^^^^^
  File "C:\Users\User\Desktop\Pruebas_Lab\Prueba_Jikk\.venv\Lib\site-packages\sqlalchemy\pool\base.py", line 1264, in _checkout
    fairy = _ConnectionRecord.checkout(pool)
  File "C:\Users\User\Desktop\Pruebas_Lab\Prueba_Jikk\.venv\Lib\site-packages\sqlalchemy\pool\base.py", line 711, in checkout
    rec = pool._do_get()
  File "C:\Users\User\Desktop\Pruebas_Lab\Prueba_Jikk\.venv\Lib\site-packages\sqlalchemy\pool\impl.py", line 177, in _do_get
    with util.safe_reraise():
         ~~~~~~~~~~~~~~~~~^^
  File "C:\Users\User\Desktop\Pruebas_Lab\Prueba_Jikk\.venv\Lib\site-packages\sqlalchemy\util\langhelpers.py", line 224, in __exit__
    raise exc_value.with_traceback(exc_tb)
  File "C:\Users\User\Desktop\Pruebas_Lab\Prueba_Jikk\.venv\Lib\site-packages\sqlalchemy\pool\impl.py", line 175, in _do_get
    return self._create_connection()
           ~~~~~~~~~~~~~~~~~~~~~~~^^
  File "C:\Users\User\Desktop\Pruebas_Lab\Prueba_Jikk\.venv\Lib\site-packages\sqlalchemy\pool\base.py", line 388, in _create_connection
    return _ConnectionRecord(self)
  File "C:\Users\User\Desktop\Pruebas_Lab\Prueba_Jikk\.venv\Lib\site-packages\sqlalchemy\pool\base.py", line 673, in __init__
    self.__connect()
    ~~~~~~~~~~~~~~^^
  File "C:\Users\User\Desktop\Pruebas_Lab\Prueba_Jikk\.venv\Lib\site-packages\sqlalchemy\pool\base.py", line 899, in __connect
    with util.safe_reraise():
         ~~~~~~~~~~~~~~~~~^^
  File "C:\Users\User\Desktop\Pruebas_Lab\Prueba_Jikk\.venv\Lib\site-packages\sqlalchemy\util\langhelpers.py", line 224, in __exit__
    raise exc_value.with_traceback(exc_tb)
  File "C:\Users\User\Desktop\Pruebas_Lab\Prueba_Jikk\.venv\Lib\site-packages\sqlalchemy\pool\base.py", line 895, in __connect
    self.dbapi_connection = connection = pool._invoke_creator(self)
                                         ~~~~~~~~~~~~~~~~~~~~^^^^^^
  File "C:\Users\User\Desktop\Pruebas_Lab\Prueba_Jikk\.venv\Lib\site-packages\sqlalchemy\engine\create.py", line 661, in connect
    return dialect.connect(*cargs, **cparams)
           ~~~~~~~~~~~~~~~^^^^^^^^^^^^^^^^^^^
  File "C:\Users\User\Desktop\Pruebas_Lab\Prueba_Jikk\.venv\Lib\site-packages\sqlalchemy\engine\default.py", line 629, in connect
    return self.loaded_dbapi.connect(*cargs, **cparams)  # type: ignore[no-any-return]  # NOQA: E501
           ~~~~~~~~~~~~~~~~~~~~~~~~~^^^^^^^^^^^^^^^^^^^
sqlalchemy.exc.OperationalError: (pyodbc.OperationalError) ('08001', '[08001] [Microsoft][ODBC Driver 17 for SQL Server]Named Pipes Provider: Could not open a connection to SQL Server [53].  (53) (SQLDriverConnect); [08001] [Microsoft][ODBC Driver 17 for SQL Server]Login timeout expired (0); [08001] [Microsoft][ODBC Driver 17 for SQL Server]A network-related or instance-specific error has occurred while establishing a connection to SQL Server. Server is not found or not accessible. Check if instance name is correct and if SQL Server is configured to allow remote connections. For more information see SQL Server Books Online. (53)')
(Background on this error at: https://sqlalche.me/e/20/e3q8)
2025-09-04 10:01:50,539 - INFO - Iniciando carga de datos desde 'data\jobs.csv' a la tabla 'jobs'...
2025-09-04 10:02:07,753 - ERROR - Error fatal durante la carga de datos en 'jobs': (pyodbc.OperationalError) ('08001', '[08001] [Microsoft][ODBC Driver 17 for SQL Server]Named Pipes Provider: Could not open a connection to SQL Server [53].  (53) (SQLDriverConnect); [08001] [Microsoft][ODBC Driver 17 for SQL Server]Login timeout expired (0); [08001] [Microsoft][ODBC Driver 17 for SQL Server]A network-related or instance-specific error has occurred while establishing a connection to SQL Server. Server is not found or not accessible. Check if instance name is correct and if SQL Server is configured to allow remote connections. For more information see SQL Server Books Online. (53)')
(Background on this error at: https://sqlalche.me/e/20/e3q8)
Traceback (most recent call last):
  File "C:\Users\User\Desktop\Pruebas_Lab\Prueba_Jikk\.venv\Lib\site-packages\sqlalchemy\engine\base.py", line 143, in __init__
    self._dbapi_connection = engine.raw_connection()
                             ~~~~~~~~~~~~~~~~~~~~~^^
  File "C:\Users\User\Desktop\Pruebas_Lab\Prueba_Jikk\.venv\Lib\site-packages\sqlalchemy\engine\base.py", line 3301, in raw_connection
    return self.pool.connect()
           ~~~~~~~~~~~~~~~~~^^
  File "C:\Users\User\Desktop\Pruebas_Lab\Prueba_Jikk\.venv\Lib\site-packages\sqlalchemy\pool\base.py", line 447, in connect
    return _ConnectionFairy._checkout(self)
           ~~~~~~~~~~~~~~~~~~~~~~~~~~^^^^^^
  File "C:\Users\User\Desktop\Pruebas_Lab\Prueba_Jikk\.venv\Lib\site-packages\sqlalchemy\pool\base.py", line 1264, in _checkout
    fairy = _ConnectionRecord.checkout(pool)
  File "C:\Users\User\Desktop\Pruebas_Lab\Prueba_Jikk\.venv\Lib\site-packages\sqlalchemy\pool\base.py", line 711, in checkout
    rec = pool._do_get()
  File "C:\Users\User\Desktop\Pruebas_Lab\Prueba_Jikk\.venv\Lib\site-packages\sqlalchemy\pool\impl.py", line 177, in _do_get
    with util.safe_reraise():
         ~~~~~~~~~~~~~~~~~^^
  File "C:\Users\User\Desktop\Pruebas_Lab\Prueba_Jikk\.venv\Lib\site-packages\sqlalchemy\util\langhelpers.py", line 224, in __exit__
    raise exc_value.with_traceback(exc_tb)
  File "C:\Users\User\Desktop\Pruebas_Lab\Prueba_Jikk\.venv\Lib\site-packages\sqlalchemy\pool\impl.py", line 175, in _do_get
    return self._create_connection()
           ~~~~~~~~~~~~~~~~~~~~~~~^^
  File "C:\Users\User\Desktop\Pruebas_Lab\Prueba_Jikk\.venv\Lib\site-packages\sqlalchemy\pool\base.py", line 388, in _create_connection
    return _ConnectionRecord(self)
  File "C:\Users\User\Desktop\Pruebas_Lab\Prueba_Jikk\.venv\Lib\site-packages\sqlalchemy\pool\base.py", line 673, in __init__
    self.__connect()
    ~~~~~~~~~~~~~~^^
  File "C:\Users\User\Desktop\Pruebas_Lab\Prueba_Jikk\.venv\Lib\site-packages\sqlalchemy\pool\base.py", line 899, in __connect
    with util.safe_reraise():
         ~~~~~~~~~~~~~~~~~^^
  File "C:\Users\User\Desktop\Pruebas_Lab\Prueba_Jikk\.venv\Lib\site-packages\sqlalchemy\util\langhelpers.py", line 224, in __exit__
    raise exc_value.with_traceback(exc_tb)
  File "C:\Users\User\Desktop\Pruebas_Lab\Prueba_Jikk\.venv\Lib\site-packages\sqlalchemy\pool\base.py", line 895, in __connect
    self.dbapi_connection = connection = pool._invoke_creator(self)
                                         ~~~~~~~~~~~~~~~~~~~~^^^^^^
  File "C:\Users\User\Desktop\Pruebas_Lab\Prueba_Jikk\.venv\Lib\site-packages\sqlalchemy\engine\create.py", line 661, in connect
    return dialect.connect(*cargs, **cparams)
           ~~~~~~~~~~~~~~~^^^^^^^^^^^^^^^^^^^
  File "C:\Users\User\Desktop\Pruebas_Lab\Prueba_Jikk\.venv\Lib\site-packages\sqlalchemy\engine\default.py", line 629, in connect
    return self.loaded_dbapi.connect(*cargs, **cparams)  # type: ignore[no-any-return]  # NOQA: E501
           ~~~~~~~~~~~~~~~~~~~~~~~~~^^^^^^^^^^^^^^^^^^^
pyodbc.OperationalError: ('08001', '[08001] [Microsoft][ODBC Driver 17 for SQL Server]Named Pipes Provider: Could not open a connection to SQL Server [53].  (53) (SQLDriverConnect); [08001] [Microsoft][ODBC Driver 17 for SQL Server]Login timeout expired (0); [08001] [Microsoft][ODBC Driver 17 for SQL Server]A network-related or instance-specific error has occurred while establishing a connection to SQL Server. Server is not found or not accessible. Check if instance name is correct and if SQL Server is configured to allow remote connections. For more information see SQL Server Books Online. (53)')

The above exception was the direct cause of the following exception:

Traceback (most recent call last):
  File "c:\Users\User\Desktop\Pruebas_Lab\Prueba_Jikk\historico.py", line 38, in load_data_from_csv
    chunk.to_sql(table_name, con=engine, if_exists='append', index=False)
    ~~~~~~~~~~~~^^^^^^^^^^^^^^^^^^^^^^^^^^^^^^^^^^^^^^^^^^^^^^^^^^^^^^^^^
  File "C:\Users\User\Desktop\Pruebas_Lab\Prueba_Jikk\.venv\Lib\site-packages\pandas\util\_decorators.py", line 333, in wrapper
    return func(*args, **kwargs)
  File "C:\Users\User\Desktop\Pruebas_Lab\Prueba_Jikk\.venv\Lib\site-packages\pandas\core\generic.py", line 3106, in to_sql
    return sql.to_sql(
           ~~~~~~~~~~^
        self,
        ^^^^^
    ...<8 lines>...
        method=method,
        ^^^^^^^^^^^^^^
    )
    ^
  File "C:\Users\User\Desktop\Pruebas_Lab\Prueba_Jikk\.venv\Lib\site-packages\pandas\io\sql.py", line 843, in to_sql
    with pandasSQL_builder(con, schema=schema, need_transaction=True) as pandas_sql:
         ~~~~~~~~~~~~~~~~~^^^^^^^^^^^^^^^^^^^^^^^^^^^^^^^^^^^^^^^^^^^
  File "C:\Users\User\Desktop\Pruebas_Lab\Prueba_Jikk\.venv\Lib\site-packages\pandas\io\sql.py", line 908, in pandasSQL_builder
    return SQLDatabase(con, schema, need_transaction)
  File "C:\Users\User\Desktop\Pruebas_Lab\Prueba_Jikk\.venv\Lib\site-packages\pandas\io\sql.py", line 1648, in __init__
    con = self.exit_stack.enter_context(con.connect())
                                        ~~~~~~~~~~~^^
  File "C:\Users\User\Desktop\Pruebas_Lab\Prueba_Jikk\.venv\Lib\site-packages\sqlalchemy\engine\base.py", line 3277, in connect
    return self._connection_cls(self)
           ~~~~~~~~~~~~~~~~~~~~^^^^^^
  File "C:\Users\User\Desktop\Pruebas_Lab\Prueba_Jikk\.venv\Lib\site-packages\sqlalchemy\engine\base.py", line 145, in __init__
    Connection._handle_dbapi_exception_noconnection(
    ~~~~~~~~~~~~~~~~~~~~~~~~~~~~~~~~~~~~~~~~~~~~~~~^
        err, dialect, engine
        ^^^^^^^^^^^^^^^^^^^^
    )
    ^
  File "C:\Users\User\Desktop\Pruebas_Lab\Prueba_Jikk\.venv\Lib\site-packages\sqlalchemy\engine\base.py", line 2440, in _handle_dbapi_exception_noconnection
    raise sqlalchemy_exception.with_traceback(exc_info[2]) from e
  File "C:\Users\User\Desktop\Pruebas_Lab\Prueba_Jikk\.venv\Lib\site-packages\sqlalchemy\engine\base.py", line 143, in __init__
    self._dbapi_connection = engine.raw_connection()
                             ~~~~~~~~~~~~~~~~~~~~~^^
  File "C:\Users\User\Desktop\Pruebas_Lab\Prueba_Jikk\.venv\Lib\site-packages\sqlalchemy\engine\base.py", line 3301, in raw_connection
    return self.pool.connect()
           ~~~~~~~~~~~~~~~~~^^
  File "C:\Users\User\Desktop\Pruebas_Lab\Prueba_Jikk\.venv\Lib\site-packages\sqlalchemy\pool\base.py", line 447, in connect
    return _ConnectionFairy._checkout(self)
           ~~~~~~~~~~~~~~~~~~~~~~~~~~^^^^^^
  File "C:\Users\User\Desktop\Pruebas_Lab\Prueba_Jikk\.venv\Lib\site-packages\sqlalchemy\pool\base.py", line 1264, in _checkout
    fairy = _ConnectionRecord.checkout(pool)
  File "C:\Users\User\Desktop\Pruebas_Lab\Prueba_Jikk\.venv\Lib\site-packages\sqlalchemy\pool\base.py", line 711, in checkout
    rec = pool._do_get()
  File "C:\Users\User\Desktop\Pruebas_Lab\Prueba_Jikk\.venv\Lib\site-packages\sqlalchemy\pool\impl.py", line 177, in _do_get
    with util.safe_reraise():
         ~~~~~~~~~~~~~~~~~^^
  File "C:\Users\User\Desktop\Pruebas_Lab\Prueba_Jikk\.venv\Lib\site-packages\sqlalchemy\util\langhelpers.py", line 224, in __exit__
    raise exc_value.with_traceback(exc_tb)
  File "C:\Users\User\Desktop\Pruebas_Lab\Prueba_Jikk\.venv\Lib\site-packages\sqlalchemy\pool\impl.py", line 175, in _do_get
    return self._create_connection()
           ~~~~~~~~~~~~~~~~~~~~~~~^^
  File "C:\Users\User\Desktop\Pruebas_Lab\Prueba_Jikk\.venv\Lib\site-packages\sqlalchemy\pool\base.py", line 388, in _create_connection
    return _ConnectionRecord(self)
  File "C:\Users\User\Desktop\Pruebas_Lab\Prueba_Jikk\.venv\Lib\site-packages\sqlalchemy\pool\base.py", line 673, in __init__
    self.__connect()
    ~~~~~~~~~~~~~~^^
  File "C:\Users\User\Desktop\Pruebas_Lab\Prueba_Jikk\.venv\Lib\site-packages\sqlalchemy\pool\base.py", line 899, in __connect
    with util.safe_reraise():
         ~~~~~~~~~~~~~~~~~^^
  File "C:\Users\User\Desktop\Pruebas_Lab\Prueba_Jikk\.venv\Lib\site-packages\sqlalchemy\util\langhelpers.py", line 224, in __exit__
    raise exc_value.with_traceback(exc_tb)
  File "C:\Users\User\Desktop\Pruebas_Lab\Prueba_Jikk\.venv\Lib\site-packages\sqlalchemy\pool\base.py", line 895, in __connect
    self.dbapi_connection = connection = pool._invoke_creator(self)
                                         ~~~~~~~~~~~~~~~~~~~~^^^^^^
  File "C:\Users\User\Desktop\Pruebas_Lab\Prueba_Jikk\.venv\Lib\site-packages\sqlalchemy\engine\create.py", line 661, in connect
    return dialect.connect(*cargs, **cparams)
           ~~~~~~~~~~~~~~~^^^^^^^^^^^^^^^^^^^
  File "C:\Users\User\Desktop\Pruebas_Lab\Prueba_Jikk\.venv\Lib\site-packages\sqlalchemy\engine\default.py", line 629, in connect
    return self.loaded_dbapi.connect(*cargs, **cparams)  # type: ignore[no-any-return]  # NOQA: E501
           ~~~~~~~~~~~~~~~~~~~~~~~~~^^^^^^^^^^^^^^^^^^^
sqlalchemy.exc.OperationalError: (pyodbc.OperationalError) ('08001', '[08001] [Microsoft][ODBC Driver 17 for SQL Server]Named Pipes Provider: Could not open a connection to SQL Server [53].  (53) (SQLDriverConnect); [08001] [Microsoft][ODBC Driver 17 for SQL Server]Login timeout expired (0); [08001] [Microsoft][ODBC Driver 17 for SQL Server]A network-related or instance-specific error has occurred while establishing a connection to SQL Server. Server is not found or not accessible. Check if instance name is correct and if SQL Server is configured to allow remote connections. For more information see SQL Server Books Online. (53)')
(Background on this error at: https://sqlalche.me/e/20/e3q8)
2025-09-04 10:02:07,759 - INFO - Iniciando carga de datos desde 'data\hired_employees.csv' a la tabla 'hired_employees'...
2025-09-04 10:02:23,944 - ERROR - Error fatal durante la carga de datos en 'hired_employees': (pyodbc.OperationalError) ('08001', '[08001] [Microsoft][ODBC Driver 17 for SQL Server]Named Pipes Provider: Could not open a connection to SQL Server [53].  (53) (SQLDriverConnect); [08001] [Microsoft][ODBC Driver 17 for SQL Server]Login timeout expired (0); [08001] [Microsoft][ODBC Driver 17 for SQL Server]A network-related or instance-specific error has occurred while establishing a connection to SQL Server. Server is not found or not accessible. Check if instance name is correct and if SQL Server is configured to allow remote connections. For more information see SQL Server Books Online. (53)')
(Background on this error at: https://sqlalche.me/e/20/e3q8)
Traceback (most recent call last):
  File "C:\Users\User\Desktop\Pruebas_Lab\Prueba_Jikk\.venv\Lib\site-packages\sqlalchemy\engine\base.py", line 143, in __init__
    self._dbapi_connection = engine.raw_connection()
                             ~~~~~~~~~~~~~~~~~~~~~^^
  File "C:\Users\User\Desktop\Pruebas_Lab\Prueba_Jikk\.venv\Lib\site-packages\sqlalchemy\engine\base.py", line 3301, in raw_connection
    return self.pool.connect()
           ~~~~~~~~~~~~~~~~~^^
  File "C:\Users\User\Desktop\Pruebas_Lab\Prueba_Jikk\.venv\Lib\site-packages\sqlalchemy\pool\base.py", line 447, in connect
    return _ConnectionFairy._checkout(self)
           ~~~~~~~~~~~~~~~~~~~~~~~~~~^^^^^^
  File "C:\Users\User\Desktop\Pruebas_Lab\Prueba_Jikk\.venv\Lib\site-packages\sqlalchemy\pool\base.py", line 1264, in _checkout
    fairy = _ConnectionRecord.checkout(pool)
  File "C:\Users\User\Desktop\Pruebas_Lab\Prueba_Jikk\.venv\Lib\site-packages\sqlalchemy\pool\base.py", line 711, in checkout
    rec = pool._do_get()
  File "C:\Users\User\Desktop\Pruebas_Lab\Prueba_Jikk\.venv\Lib\site-packages\sqlalchemy\pool\impl.py", line 177, in _do_get
    with util.safe_reraise():
         ~~~~~~~~~~~~~~~~~^^
  File "C:\Users\User\Desktop\Pruebas_Lab\Prueba_Jikk\.venv\Lib\site-packages\sqlalchemy\util\langhelpers.py", line 224, in __exit__
    raise exc_value.with_traceback(exc_tb)
  File "C:\Users\User\Desktop\Pruebas_Lab\Prueba_Jikk\.venv\Lib\site-packages\sqlalchemy\pool\impl.py", line 175, in _do_get
    return self._create_connection()
           ~~~~~~~~~~~~~~~~~~~~~~~^^
  File "C:\Users\User\Desktop\Pruebas_Lab\Prueba_Jikk\.venv\Lib\site-packages\sqlalchemy\pool\base.py", line 388, in _create_connection
    return _ConnectionRecord(self)
  File "C:\Users\User\Desktop\Pruebas_Lab\Prueba_Jikk\.venv\Lib\site-packages\sqlalchemy\pool\base.py", line 673, in __init__
    self.__connect()
    ~~~~~~~~~~~~~~^^
  File "C:\Users\User\Desktop\Pruebas_Lab\Prueba_Jikk\.venv\Lib\site-packages\sqlalchemy\pool\base.py", line 899, in __connect
    with util.safe_reraise():
         ~~~~~~~~~~~~~~~~~^^
  File "C:\Users\User\Desktop\Pruebas_Lab\Prueba_Jikk\.venv\Lib\site-packages\sqlalchemy\util\langhelpers.py", line 224, in __exit__
    raise exc_value.with_traceback(exc_tb)
  File "C:\Users\User\Desktop\Pruebas_Lab\Prueba_Jikk\.venv\Lib\site-packages\sqlalchemy\pool\base.py", line 895, in __connect
    self.dbapi_connection = connection = pool._invoke_creator(self)
                                         ~~~~~~~~~~~~~~~~~~~~^^^^^^
  File "C:\Users\User\Desktop\Pruebas_Lab\Prueba_Jikk\.venv\Lib\site-packages\sqlalchemy\engine\create.py", line 661, in connect
    return dialect.connect(*cargs, **cparams)
           ~~~~~~~~~~~~~~~^^^^^^^^^^^^^^^^^^^
  File "C:\Users\User\Desktop\Pruebas_Lab\Prueba_Jikk\.venv\Lib\site-packages\sqlalchemy\engine\default.py", line 629, in connect
    return self.loaded_dbapi.connect(*cargs, **cparams)  # type: ignore[no-any-return]  # NOQA: E501
           ~~~~~~~~~~~~~~~~~~~~~~~~~^^^^^^^^^^^^^^^^^^^
pyodbc.OperationalError: ('08001', '[08001] [Microsoft][ODBC Driver 17 for SQL Server]Named Pipes Provider: Could not open a connection to SQL Server [53].  (53) (SQLDriverConnect); [08001] [Microsoft][ODBC Driver 17 for SQL Server]Login timeout expired (0); [08001] [Microsoft][ODBC Driver 17 for SQL Server]A network-related or instance-specific error has occurred while establishing a connection to SQL Server. Server is not found or not accessible. Check if instance name is correct and if SQL Server is configured to allow remote connections. For more information see SQL Server Books Online. (53)')

The above exception was the direct cause of the following exception:

Traceback (most recent call last):
  File "c:\Users\User\Desktop\Pruebas_Lab\Prueba_Jikk\historico.py", line 38, in load_data_from_csv
    chunk.to_sql(table_name, con=engine, if_exists='append', index=False)
    ~~~~~~~~~~~~^^^^^^^^^^^^^^^^^^^^^^^^^^^^^^^^^^^^^^^^^^^^^^^^^^^^^^^^^
  File "C:\Users\User\Desktop\Pruebas_Lab\Prueba_Jikk\.venv\Lib\site-packages\pandas\util\_decorators.py", line 333, in wrapper
    return func(*args, **kwargs)
  File "C:\Users\User\Desktop\Pruebas_Lab\Prueba_Jikk\.venv\Lib\site-packages\pandas\core\generic.py", line 3106, in to_sql
    return sql.to_sql(
           ~~~~~~~~~~^
        self,
        ^^^^^
    ...<8 lines>...
        method=method,
        ^^^^^^^^^^^^^^
    )
    ^
  File "C:\Users\User\Desktop\Pruebas_Lab\Prueba_Jikk\.venv\Lib\site-packages\pandas\io\sql.py", line 843, in to_sql
    with pandasSQL_builder(con, schema=schema, need_transaction=True) as pandas_sql:
         ~~~~~~~~~~~~~~~~~^^^^^^^^^^^^^^^^^^^^^^^^^^^^^^^^^^^^^^^^^^^
  File "C:\Users\User\Desktop\Pruebas_Lab\Prueba_Jikk\.venv\Lib\site-packages\pandas\io\sql.py", line 908, in pandasSQL_builder
    return SQLDatabase(con, schema, need_transaction)
  File "C:\Users\User\Desktop\Pruebas_Lab\Prueba_Jikk\.venv\Lib\site-packages\pandas\io\sql.py", line 1648, in __init__
    con = self.exit_stack.enter_context(con.connect())
                                        ~~~~~~~~~~~^^
  File "C:\Users\User\Desktop\Pruebas_Lab\Prueba_Jikk\.venv\Lib\site-packages\sqlalchemy\engine\base.py", line 3277, in connect
    return self._connection_cls(self)
           ~~~~~~~~~~~~~~~~~~~~^^^^^^
  File "C:\Users\User\Desktop\Pruebas_Lab\Prueba_Jikk\.venv\Lib\site-packages\sqlalchemy\engine\base.py", line 145, in __init__
    Connection._handle_dbapi_exception_noconnection(
    ~~~~~~~~~~~~~~~~~~~~~~~~~~~~~~~~~~~~~~~~~~~~~~~^
        err, dialect, engine
        ^^^^^^^^^^^^^^^^^^^^
    )
    ^
  File "C:\Users\User\Desktop\Pruebas_Lab\Prueba_Jikk\.venv\Lib\site-packages\sqlalchemy\engine\base.py", line 2440, in _handle_dbapi_exception_noconnection
    raise sqlalchemy_exception.with_traceback(exc_info[2]) from e
  File "C:\Users\User\Desktop\Pruebas_Lab\Prueba_Jikk\.venv\Lib\site-packages\sqlalchemy\engine\base.py", line 143, in __init__
    self._dbapi_connection = engine.raw_connection()
                             ~~~~~~~~~~~~~~~~~~~~~^^
  File "C:\Users\User\Desktop\Pruebas_Lab\Prueba_Jikk\.venv\Lib\site-packages\sqlalchemy\engine\base.py", line 3301, in raw_connection
    return self.pool.connect()
           ~~~~~~~~~~~~~~~~~^^
  File "C:\Users\User\Desktop\Pruebas_Lab\Prueba_Jikk\.venv\Lib\site-packages\sqlalchemy\pool\base.py", line 447, in connect
    return _ConnectionFairy._checkout(self)
           ~~~~~~~~~~~~~~~~~~~~~~~~~~^^^^^^
  File "C:\Users\User\Desktop\Pruebas_Lab\Prueba_Jikk\.venv\Lib\site-packages\sqlalchemy\pool\base.py", line 1264, in _checkout
    fairy = _ConnectionRecord.checkout(pool)
  File "C:\Users\User\Desktop\Pruebas_Lab\Prueba_Jikk\.venv\Lib\site-packages\sqlalchemy\pool\base.py", line 711, in checkout
    rec = pool._do_get()
  File "C:\Users\User\Desktop\Pruebas_Lab\Prueba_Jikk\.venv\Lib\site-packages\sqlalchemy\pool\impl.py", line 177, in _do_get
    with util.safe_reraise():
         ~~~~~~~~~~~~~~~~~^^
  File "C:\Users\User\Desktop\Pruebas_Lab\Prueba_Jikk\.venv\Lib\site-packages\sqlalchemy\util\langhelpers.py", line 224, in __exit__
    raise exc_value.with_traceback(exc_tb)
  File "C:\Users\User\Desktop\Pruebas_Lab\Prueba_Jikk\.venv\Lib\site-packages\sqlalchemy\pool\impl.py", line 175, in _do_get
    return self._create_connection()
           ~~~~~~~~~~~~~~~~~~~~~~~^^
  File "C:\Users\User\Desktop\Pruebas_Lab\Prueba_Jikk\.venv\Lib\site-packages\sqlalchemy\pool\base.py", line 388, in _create_connection
    return _ConnectionRecord(self)
  File "C:\Users\User\Desktop\Pruebas_Lab\Prueba_Jikk\.venv\Lib\site-packages\sqlalchemy\pool\base.py", line 673, in __init__
    self.__connect()
    ~~~~~~~~~~~~~~^^
  File "C:\Users\User\Desktop\Pruebas_Lab\Prueba_Jikk\.venv\Lib\site-packages\sqlalchemy\pool\base.py", line 899, in __connect
    with util.safe_reraise():
         ~~~~~~~~~~~~~~~~~^^
  File "C:\Users\User\Desktop\Pruebas_Lab\Prueba_Jikk\.venv\Lib\site-packages\sqlalchemy\util\langhelpers.py", line 224, in __exit__
    raise exc_value.with_traceback(exc_tb)
  File "C:\Users\User\Desktop\Pruebas_Lab\Prueba_Jikk\.venv\Lib\site-packages\sqlalchemy\pool\base.py", line 895, in __connect
    self.dbapi_connection = connection = pool._invoke_creator(self)
                                         ~~~~~~~~~~~~~~~~~~~~^^^^^^
  File "C:\Users\User\Desktop\Pruebas_Lab\Prueba_Jikk\.venv\Lib\site-packages\sqlalchemy\engine\create.py", line 661, in connect
    return dialect.connect(*cargs, **cparams)
           ~~~~~~~~~~~~~~~^^^^^^^^^^^^^^^^^^^
  File "C:\Users\User\Desktop\Pruebas_Lab\Prueba_Jikk\.venv\Lib\site-packages\sqlalchemy\engine\default.py", line 629, in connect
    return self.loaded_dbapi.connect(*cargs, **cparams)  # type: ignore[no-any-return]  # NOQA: E501
           ~~~~~~~~~~~~~~~~~~~~~~~~~^^^^^^^^^^^^^^^^^^^
sqlalchemy.exc.OperationalError: (pyodbc.OperationalError) ('08001', '[08001] [Microsoft][ODBC Driver 17 for SQL Server]Named Pipes Provider: Could not open a connection to SQL Server [53].  (53) (SQLDriverConnect); [08001] [Microsoft][ODBC Driver 17 for SQL Server]Login timeout expired (0); [08001] [Microsoft][ODBC Driver 17 for SQL Server]A network-related or instance-specific error has occurred while establishing a connection to SQL Server. Server is not found or not accessible. Check if instance name is correct and if SQL Server is configured to allow remote connections. For more information see SQL Server Books Online. (53)')
(Background on this error at: https://sqlalche.me/e/20/e3q8)
2025-09-04 10:05:29,680 - INFO - Iniciando carga de datos desde 'data\departments.csv' a la tabla 'departments'...
2025-09-04 10:05:46,299 - ERROR - Error fatal durante la carga de datos en 'departments': (pyodbc.OperationalError) ('08001', '[08001] [Microsoft][ODBC Driver 17 for SQL Server]Named Pipes Provider: Could not open a connection to SQL Server [53].  (53) (SQLDriverConnect); [08001] [Microsoft][ODBC Driver 17 for SQL Server]Login timeout expired (0); [08001] [Microsoft][ODBC Driver 17 for SQL Server]A network-related or instance-specific error has occurred while establishing a connection to SQL Server. Server is not found or not accessible. Check if instance name is correct and if SQL Server is configured to allow remote connections. For more information see SQL Server Books Online. (53)')
(Background on this error at: https://sqlalche.me/e/20/e3q8)
Traceback (most recent call last):
  File "C:\Users\User\Desktop\Pruebas_Lab\Prueba_Jikk\.venv\Lib\site-packages\sqlalchemy\engine\base.py", line 143, in __init__
    self._dbapi_connection = engine.raw_connection()
                             ~~~~~~~~~~~~~~~~~~~~~^^
  File "C:\Users\User\Desktop\Pruebas_Lab\Prueba_Jikk\.venv\Lib\site-packages\sqlalchemy\engine\base.py", line 3301, in raw_connection
    return self.pool.connect()
           ~~~~~~~~~~~~~~~~~^^
  File "C:\Users\User\Desktop\Pruebas_Lab\Prueba_Jikk\.venv\Lib\site-packages\sqlalchemy\pool\base.py", line 447, in connect
    return _ConnectionFairy._checkout(self)
           ~~~~~~~~~~~~~~~~~~~~~~~~~~^^^^^^
  File "C:\Users\User\Desktop\Pruebas_Lab\Prueba_Jikk\.venv\Lib\site-packages\sqlalchemy\pool\base.py", line 1264, in _checkout
    fairy = _ConnectionRecord.checkout(pool)
  File "C:\Users\User\Desktop\Pruebas_Lab\Prueba_Jikk\.venv\Lib\site-packages\sqlalchemy\pool\base.py", line 711, in checkout
    rec = pool._do_get()
  File "C:\Users\User\Desktop\Pruebas_Lab\Prueba_Jikk\.venv\Lib\site-packages\sqlalchemy\pool\impl.py", line 177, in _do_get
    with util.safe_reraise():
         ~~~~~~~~~~~~~~~~~^^
  File "C:\Users\User\Desktop\Pruebas_Lab\Prueba_Jikk\.venv\Lib\site-packages\sqlalchemy\util\langhelpers.py", line 224, in __exit__
    raise exc_value.with_traceback(exc_tb)
  File "C:\Users\User\Desktop\Pruebas_Lab\Prueba_Jikk\.venv\Lib\site-packages\sqlalchemy\pool\impl.py", line 175, in _do_get
    return self._create_connection()
           ~~~~~~~~~~~~~~~~~~~~~~~^^
  File "C:\Users\User\Desktop\Pruebas_Lab\Prueba_Jikk\.venv\Lib\site-packages\sqlalchemy\pool\base.py", line 388, in _create_connection
    return _ConnectionRecord(self)
  File "C:\Users\User\Desktop\Pruebas_Lab\Prueba_Jikk\.venv\Lib\site-packages\sqlalchemy\pool\base.py", line 673, in __init__
    self.__connect()
    ~~~~~~~~~~~~~~^^
  File "C:\Users\User\Desktop\Pruebas_Lab\Prueba_Jikk\.venv\Lib\site-packages\sqlalchemy\pool\base.py", line 899, in __connect
    with util.safe_reraise():
         ~~~~~~~~~~~~~~~~~^^
  File "C:\Users\User\Desktop\Pruebas_Lab\Prueba_Jikk\.venv\Lib\site-packages\sqlalchemy\util\langhelpers.py", line 224, in __exit__
    raise exc_value.with_traceback(exc_tb)
  File "C:\Users\User\Desktop\Pruebas_Lab\Prueba_Jikk\.venv\Lib\site-packages\sqlalchemy\pool\base.py", line 895, in __connect
    self.dbapi_connection = connection = pool._invoke_creator(self)
                                         ~~~~~~~~~~~~~~~~~~~~^^^^^^
  File "C:\Users\User\Desktop\Pruebas_Lab\Prueba_Jikk\.venv\Lib\site-packages\sqlalchemy\engine\create.py", line 661, in connect
    return dialect.connect(*cargs, **cparams)
           ~~~~~~~~~~~~~~~^^^^^^^^^^^^^^^^^^^
  File "C:\Users\User\Desktop\Pruebas_Lab\Prueba_Jikk\.venv\Lib\site-packages\sqlalchemy\engine\default.py", line 629, in connect
    return self.loaded_dbapi.connect(*cargs, **cparams)  # type: ignore[no-any-return]  # NOQA: E501
           ~~~~~~~~~~~~~~~~~~~~~~~~~^^^^^^^^^^^^^^^^^^^
pyodbc.OperationalError: ('08001', '[08001] [Microsoft][ODBC Driver 17 for SQL Server]Named Pipes Provider: Could not open a connection to SQL Server [53].  (53) (SQLDriverConnect); [08001] [Microsoft][ODBC Driver 17 for SQL Server]Login timeout expired (0); [08001] [Microsoft][ODBC Driver 17 for SQL Server]A network-related or instance-specific error has occurred while establishing a connection to SQL Server. Server is not found or not accessible. Check if instance name is correct and if SQL Server is configured to allow remote connections. For more information see SQL Server Books Online. (53)')

The above exception was the direct cause of the following exception:

Traceback (most recent call last):
  File "c:\Users\User\Desktop\Pruebas_Lab\Prueba_Jikk\historico.py", line 38, in load_data_from_csv
    chunk.to_sql(table_name, con=engine, if_exists='append', index=False)
    ~~~~~~~~~~~~^^^^^^^^^^^^^^^^^^^^^^^^^^^^^^^^^^^^^^^^^^^^^^^^^^^^^^^^^
  File "C:\Users\User\Desktop\Pruebas_Lab\Prueba_Jikk\.venv\Lib\site-packages\pandas\util\_decorators.py", line 333, in wrapper
    return func(*args, **kwargs)
  File "C:\Users\User\Desktop\Pruebas_Lab\Prueba_Jikk\.venv\Lib\site-packages\pandas\core\generic.py", line 3106, in to_sql
    return sql.to_sql(
           ~~~~~~~~~~^
        self,
        ^^^^^
    ...<8 lines>...
        method=method,
        ^^^^^^^^^^^^^^
    )
    ^
  File "C:\Users\User\Desktop\Pruebas_Lab\Prueba_Jikk\.venv\Lib\site-packages\pandas\io\sql.py", line 843, in to_sql
    with pandasSQL_builder(con, schema=schema, need_transaction=True) as pandas_sql:
         ~~~~~~~~~~~~~~~~~^^^^^^^^^^^^^^^^^^^^^^^^^^^^^^^^^^^^^^^^^^^
  File "C:\Users\User\Desktop\Pruebas_Lab\Prueba_Jikk\.venv\Lib\site-packages\pandas\io\sql.py", line 908, in pandasSQL_builder
    return SQLDatabase(con, schema, need_transaction)
  File "C:\Users\User\Desktop\Pruebas_Lab\Prueba_Jikk\.venv\Lib\site-packages\pandas\io\sql.py", line 1648, in __init__
    con = self.exit_stack.enter_context(con.connect())
                                        ~~~~~~~~~~~^^
  File "C:\Users\User\Desktop\Pruebas_Lab\Prueba_Jikk\.venv\Lib\site-packages\sqlalchemy\engine\base.py", line 3277, in connect
    return self._connection_cls(self)
           ~~~~~~~~~~~~~~~~~~~~^^^^^^
  File "C:\Users\User\Desktop\Pruebas_Lab\Prueba_Jikk\.venv\Lib\site-packages\sqlalchemy\engine\base.py", line 145, in __init__
    Connection._handle_dbapi_exception_noconnection(
    ~~~~~~~~~~~~~~~~~~~~~~~~~~~~~~~~~~~~~~~~~~~~~~~^
        err, dialect, engine
        ^^^^^^^^^^^^^^^^^^^^
    )
    ^
  File "C:\Users\User\Desktop\Pruebas_Lab\Prueba_Jikk\.venv\Lib\site-packages\sqlalchemy\engine\base.py", line 2440, in _handle_dbapi_exception_noconnection
    raise sqlalchemy_exception.with_traceback(exc_info[2]) from e
  File "C:\Users\User\Desktop\Pruebas_Lab\Prueba_Jikk\.venv\Lib\site-packages\sqlalchemy\engine\base.py", line 143, in __init__
    self._dbapi_connection = engine.raw_connection()
                             ~~~~~~~~~~~~~~~~~~~~~^^
  File "C:\Users\User\Desktop\Pruebas_Lab\Prueba_Jikk\.venv\Lib\site-packages\sqlalchemy\engine\base.py", line 3301, in raw_connection
    return self.pool.connect()
           ~~~~~~~~~~~~~~~~~^^
  File "C:\Users\User\Desktop\Pruebas_Lab\Prueba_Jikk\.venv\Lib\site-packages\sqlalchemy\pool\base.py", line 447, in connect
    return _ConnectionFairy._checkout(self)
           ~~~~~~~~~~~~~~~~~~~~~~~~~~^^^^^^
  File "C:\Users\User\Desktop\Pruebas_Lab\Prueba_Jikk\.venv\Lib\site-packages\sqlalchemy\pool\base.py", line 1264, in _checkout
    fairy = _ConnectionRecord.checkout(pool)
  File "C:\Users\User\Desktop\Pruebas_Lab\Prueba_Jikk\.venv\Lib\site-packages\sqlalchemy\pool\base.py", line 711, in checkout
    rec = pool._do_get()
  File "C:\Users\User\Desktop\Pruebas_Lab\Prueba_Jikk\.venv\Lib\site-packages\sqlalchemy\pool\impl.py", line 177, in _do_get
    with util.safe_reraise():
         ~~~~~~~~~~~~~~~~~^^
  File "C:\Users\User\Desktop\Pruebas_Lab\Prueba_Jikk\.venv\Lib\site-packages\sqlalchemy\util\langhelpers.py", line 224, in __exit__
    raise exc_value.with_traceback(exc_tb)
  File "C:\Users\User\Desktop\Pruebas_Lab\Prueba_Jikk\.venv\Lib\site-packages\sqlalchemy\pool\impl.py", line 175, in _do_get
    return self._create_connection()
           ~~~~~~~~~~~~~~~~~~~~~~~^^
  File "C:\Users\User\Desktop\Pruebas_Lab\Prueba_Jikk\.venv\Lib\site-packages\sqlalchemy\pool\base.py", line 388, in _create_connection
    return _ConnectionRecord(self)
  File "C:\Users\User\Desktop\Pruebas_Lab\Prueba_Jikk\.venv\Lib\site-packages\sqlalchemy\pool\base.py", line 673, in __init__
    self.__connect()
    ~~~~~~~~~~~~~~^^
  File "C:\Users\User\Desktop\Pruebas_Lab\Prueba_Jikk\.venv\Lib\site-packages\sqlalchemy\pool\base.py", line 899, in __connect
    with util.safe_reraise():
         ~~~~~~~~~~~~~~~~~^^
  File "C:\Users\User\Desktop\Pruebas_Lab\Prueba_Jikk\.venv\Lib\site-packages\sqlalchemy\util\langhelpers.py", line 224, in __exit__
    raise exc_value.with_traceback(exc_tb)
  File "C:\Users\User\Desktop\Pruebas_Lab\Prueba_Jikk\.venv\Lib\site-packages\sqlalchemy\pool\base.py", line 895, in __connect
    self.dbapi_connection = connection = pool._invoke_creator(self)
                                         ~~~~~~~~~~~~~~~~~~~~^^^^^^
  File "C:\Users\User\Desktop\Pruebas_Lab\Prueba_Jikk\.venv\Lib\site-packages\sqlalchemy\engine\create.py", line 661, in connect
    return dialect.connect(*cargs, **cparams)
           ~~~~~~~~~~~~~~~^^^^^^^^^^^^^^^^^^^
  File "C:\Users\User\Desktop\Pruebas_Lab\Prueba_Jikk\.venv\Lib\site-packages\sqlalchemy\engine\default.py", line 629, in connect
    return self.loaded_dbapi.connect(*cargs, **cparams)  # type: ignore[no-any-return]  # NOQA: E501
           ~~~~~~~~~~~~~~~~~~~~~~~~~^^^^^^^^^^^^^^^^^^^
sqlalchemy.exc.OperationalError: (pyodbc.OperationalError) ('08001', '[08001] [Microsoft][ODBC Driver 17 for SQL Server]Named Pipes Provider: Could not open a connection to SQL Server [53].  (53) (SQLDriverConnect); [08001] [Microsoft][ODBC Driver 17 for SQL Server]Login timeout expired (0); [08001] [Microsoft][ODBC Driver 17 for SQL Server]A network-related or instance-specific error has occurred while establishing a connection to SQL Server. Server is not found or not accessible. Check if instance name is correct and if SQL Server is configured to allow remote connections. For more information see SQL Server Books Online. (53)')
(Background on this error at: https://sqlalche.me/e/20/e3q8)
2025-09-04 10:05:46,310 - INFO - Iniciando carga de datos desde 'data\jobs.csv' a la tabla 'jobs'...
2025-09-04 10:06:03,482 - ERROR - Error fatal durante la carga de datos en 'jobs': (pyodbc.OperationalError) ('08001', '[08001] [Microsoft][ODBC Driver 17 for SQL Server]Named Pipes Provider: Could not open a connection to SQL Server [53].  (53) (SQLDriverConnect); [08001] [Microsoft][ODBC Driver 17 for SQL Server]Login timeout expired (0); [08001] [Microsoft][ODBC Driver 17 for SQL Server]A network-related or instance-specific error has occurred while establishing a connection to SQL Server. Server is not found or not accessible. Check if instance name is correct and if SQL Server is configured to allow remote connections. For more information see SQL Server Books Online. (53)')
(Background on this error at: https://sqlalche.me/e/20/e3q8)
Traceback (most recent call last):
  File "C:\Users\User\Desktop\Pruebas_Lab\Prueba_Jikk\.venv\Lib\site-packages\sqlalchemy\engine\base.py", line 143, in __init__
    self._dbapi_connection = engine.raw_connection()
                             ~~~~~~~~~~~~~~~~~~~~~^^
  File "C:\Users\User\Desktop\Pruebas_Lab\Prueba_Jikk\.venv\Lib\site-packages\sqlalchemy\engine\base.py", line 3301, in raw_connection
    return self.pool.connect()
           ~~~~~~~~~~~~~~~~~^^
  File "C:\Users\User\Desktop\Pruebas_Lab\Prueba_Jikk\.venv\Lib\site-packages\sqlalchemy\pool\base.py", line 447, in connect
    return _ConnectionFairy._checkout(self)
           ~~~~~~~~~~~~~~~~~~~~~~~~~~^^^^^^
  File "C:\Users\User\Desktop\Pruebas_Lab\Prueba_Jikk\.venv\Lib\site-packages\sqlalchemy\pool\base.py", line 1264, in _checkout
    fairy = _ConnectionRecord.checkout(pool)
  File "C:\Users\User\Desktop\Pruebas_Lab\Prueba_Jikk\.venv\Lib\site-packages\sqlalchemy\pool\base.py", line 711, in checkout
    rec = pool._do_get()
  File "C:\Users\User\Desktop\Pruebas_Lab\Prueba_Jikk\.venv\Lib\site-packages\sqlalchemy\pool\impl.py", line 177, in _do_get
    with util.safe_reraise():
         ~~~~~~~~~~~~~~~~~^^
  File "C:\Users\User\Desktop\Pruebas_Lab\Prueba_Jikk\.venv\Lib\site-packages\sqlalchemy\util\langhelpers.py", line 224, in __exit__
    raise exc_value.with_traceback(exc_tb)
  File "C:\Users\User\Desktop\Pruebas_Lab\Prueba_Jikk\.venv\Lib\site-packages\sqlalchemy\pool\impl.py", line 175, in _do_get
    return self._create_connection()
           ~~~~~~~~~~~~~~~~~~~~~~~^^
  File "C:\Users\User\Desktop\Pruebas_Lab\Prueba_Jikk\.venv\Lib\site-packages\sqlalchemy\pool\base.py", line 388, in _create_connection
    return _ConnectionRecord(self)
  File "C:\Users\User\Desktop\Pruebas_Lab\Prueba_Jikk\.venv\Lib\site-packages\sqlalchemy\pool\base.py", line 673, in __init__
    self.__connect()
    ~~~~~~~~~~~~~~^^
  File "C:\Users\User\Desktop\Pruebas_Lab\Prueba_Jikk\.venv\Lib\site-packages\sqlalchemy\pool\base.py", line 899, in __connect
    with util.safe_reraise():
         ~~~~~~~~~~~~~~~~~^^
  File "C:\Users\User\Desktop\Pruebas_Lab\Prueba_Jikk\.venv\Lib\site-packages\sqlalchemy\util\langhelpers.py", line 224, in __exit__
    raise exc_value.with_traceback(exc_tb)
  File "C:\Users\User\Desktop\Pruebas_Lab\Prueba_Jikk\.venv\Lib\site-packages\sqlalchemy\pool\base.py", line 895, in __connect
    self.dbapi_connection = connection = pool._invoke_creator(self)
                                         ~~~~~~~~~~~~~~~~~~~~^^^^^^
  File "C:\Users\User\Desktop\Pruebas_Lab\Prueba_Jikk\.venv\Lib\site-packages\sqlalchemy\engine\create.py", line 661, in connect
    return dialect.connect(*cargs, **cparams)
           ~~~~~~~~~~~~~~~^^^^^^^^^^^^^^^^^^^
  File "C:\Users\User\Desktop\Pruebas_Lab\Prueba_Jikk\.venv\Lib\site-packages\sqlalchemy\engine\default.py", line 629, in connect
    return self.loaded_dbapi.connect(*cargs, **cparams)  # type: ignore[no-any-return]  # NOQA: E501
           ~~~~~~~~~~~~~~~~~~~~~~~~~^^^^^^^^^^^^^^^^^^^
pyodbc.OperationalError: ('08001', '[08001] [Microsoft][ODBC Driver 17 for SQL Server]Named Pipes Provider: Could not open a connection to SQL Server [53].  (53) (SQLDriverConnect); [08001] [Microsoft][ODBC Driver 17 for SQL Server]Login timeout expired (0); [08001] [Microsoft][ODBC Driver 17 for SQL Server]A network-related or instance-specific error has occurred while establishing a connection to SQL Server. Server is not found or not accessible. Check if instance name is correct and if SQL Server is configured to allow remote connections. For more information see SQL Server Books Online. (53)')

The above exception was the direct cause of the following exception:

Traceback (most recent call last):
  File "c:\Users\User\Desktop\Pruebas_Lab\Prueba_Jikk\historico.py", line 38, in load_data_from_csv
    chunk.to_sql(table_name, con=engine, if_exists='append', index=False)
    ~~~~~~~~~~~~^^^^^^^^^^^^^^^^^^^^^^^^^^^^^^^^^^^^^^^^^^^^^^^^^^^^^^^^^
  File "C:\Users\User\Desktop\Pruebas_Lab\Prueba_Jikk\.venv\Lib\site-packages\pandas\util\_decorators.py", line 333, in wrapper
    return func(*args, **kwargs)
  File "C:\Users\User\Desktop\Pruebas_Lab\Prueba_Jikk\.venv\Lib\site-packages\pandas\core\generic.py", line 3106, in to_sql
    return sql.to_sql(
           ~~~~~~~~~~^
        self,
        ^^^^^
    ...<8 lines>...
        method=method,
        ^^^^^^^^^^^^^^
    )
    ^
  File "C:\Users\User\Desktop\Pruebas_Lab\Prueba_Jikk\.venv\Lib\site-packages\pandas\io\sql.py", line 843, in to_sql
    with pandasSQL_builder(con, schema=schema, need_transaction=True) as pandas_sql:
         ~~~~~~~~~~~~~~~~~^^^^^^^^^^^^^^^^^^^^^^^^^^^^^^^^^^^^^^^^^^^
  File "C:\Users\User\Desktop\Pruebas_Lab\Prueba_Jikk\.venv\Lib\site-packages\pandas\io\sql.py", line 908, in pandasSQL_builder
    return SQLDatabase(con, schema, need_transaction)
  File "C:\Users\User\Desktop\Pruebas_Lab\Prueba_Jikk\.venv\Lib\site-packages\pandas\io\sql.py", line 1648, in __init__
    con = self.exit_stack.enter_context(con.connect())
                                        ~~~~~~~~~~~^^
  File "C:\Users\User\Desktop\Pruebas_Lab\Prueba_Jikk\.venv\Lib\site-packages\sqlalchemy\engine\base.py", line 3277, in connect
    return self._connection_cls(self)
           ~~~~~~~~~~~~~~~~~~~~^^^^^^
  File "C:\Users\User\Desktop\Pruebas_Lab\Prueba_Jikk\.venv\Lib\site-packages\sqlalchemy\engine\base.py", line 145, in __init__
    Connection._handle_dbapi_exception_noconnection(
    ~~~~~~~~~~~~~~~~~~~~~~~~~~~~~~~~~~~~~~~~~~~~~~~^
        err, dialect, engine
        ^^^^^^^^^^^^^^^^^^^^
    )
    ^
  File "C:\Users\User\Desktop\Pruebas_Lab\Prueba_Jikk\.venv\Lib\site-packages\sqlalchemy\engine\base.py", line 2440, in _handle_dbapi_exception_noconnection
    raise sqlalchemy_exception.with_traceback(exc_info[2]) from e
  File "C:\Users\User\Desktop\Pruebas_Lab\Prueba_Jikk\.venv\Lib\site-packages\sqlalchemy\engine\base.py", line 143, in __init__
    self._dbapi_connection = engine.raw_connection()
                             ~~~~~~~~~~~~~~~~~~~~~^^
  File "C:\Users\User\Desktop\Pruebas_Lab\Prueba_Jikk\.venv\Lib\site-packages\sqlalchemy\engine\base.py", line 3301, in raw_connection
    return self.pool.connect()
           ~~~~~~~~~~~~~~~~~^^
  File "C:\Users\User\Desktop\Pruebas_Lab\Prueba_Jikk\.venv\Lib\site-packages\sqlalchemy\pool\base.py", line 447, in connect
    return _ConnectionFairy._checkout(self)
           ~~~~~~~~~~~~~~~~~~~~~~~~~~^^^^^^
  File "C:\Users\User\Desktop\Pruebas_Lab\Prueba_Jikk\.venv\Lib\site-packages\sqlalchemy\pool\base.py", line 1264, in _checkout
    fairy = _ConnectionRecord.checkout(pool)
  File "C:\Users\User\Desktop\Pruebas_Lab\Prueba_Jikk\.venv\Lib\site-packages\sqlalchemy\pool\base.py", line 711, in checkout
    rec = pool._do_get()
  File "C:\Users\User\Desktop\Pruebas_Lab\Prueba_Jikk\.venv\Lib\site-packages\sqlalchemy\pool\impl.py", line 177, in _do_get
    with util.safe_reraise():
         ~~~~~~~~~~~~~~~~~^^
  File "C:\Users\User\Desktop\Pruebas_Lab\Prueba_Jikk\.venv\Lib\site-packages\sqlalchemy\util\langhelpers.py", line 224, in __exit__
    raise exc_value.with_traceback(exc_tb)
  File "C:\Users\User\Desktop\Pruebas_Lab\Prueba_Jikk\.venv\Lib\site-packages\sqlalchemy\pool\impl.py", line 175, in _do_get
    return self._create_connection()
           ~~~~~~~~~~~~~~~~~~~~~~~^^
  File "C:\Users\User\Desktop\Pruebas_Lab\Prueba_Jikk\.venv\Lib\site-packages\sqlalchemy\pool\base.py", line 388, in _create_connection
    return _ConnectionRecord(self)
  File "C:\Users\User\Desktop\Pruebas_Lab\Prueba_Jikk\.venv\Lib\site-packages\sqlalchemy\pool\base.py", line 673, in __init__
    self.__connect()
    ~~~~~~~~~~~~~~^^
  File "C:\Users\User\Desktop\Pruebas_Lab\Prueba_Jikk\.venv\Lib\site-packages\sqlalchemy\pool\base.py", line 899, in __connect
    with util.safe_reraise():
         ~~~~~~~~~~~~~~~~~^^
  File "C:\Users\User\Desktop\Pruebas_Lab\Prueba_Jikk\.venv\Lib\site-packages\sqlalchemy\util\langhelpers.py", line 224, in __exit__
    raise exc_value.with_traceback(exc_tb)
  File "C:\Users\User\Desktop\Pruebas_Lab\Prueba_Jikk\.venv\Lib\site-packages\sqlalchemy\pool\base.py", line 895, in __connect
    self.dbapi_connection = connection = pool._invoke_creator(self)
                                         ~~~~~~~~~~~~~~~~~~~~^^^^^^
  File "C:\Users\User\Desktop\Pruebas_Lab\Prueba_Jikk\.venv\Lib\site-packages\sqlalchemy\engine\create.py", line 661, in connect
    return dialect.connect(*cargs, **cparams)
           ~~~~~~~~~~~~~~~^^^^^^^^^^^^^^^^^^^
  File "C:\Users\User\Desktop\Pruebas_Lab\Prueba_Jikk\.venv\Lib\site-packages\sqlalchemy\engine\default.py", line 629, in connect
    return self.loaded_dbapi.connect(*cargs, **cparams)  # type: ignore[no-any-return]  # NOQA: E501
           ~~~~~~~~~~~~~~~~~~~~~~~~~^^^^^^^^^^^^^^^^^^^
sqlalchemy.exc.OperationalError: (pyodbc.OperationalError) ('08001', '[08001] [Microsoft][ODBC Driver 17 for SQL Server]Named Pipes Provider: Could not open a connection to SQL Server [53].  (53) (SQLDriverConnect); [08001] [Microsoft][ODBC Driver 17 for SQL Server]Login timeout expired (0); [08001] [Microsoft][ODBC Driver 17 for SQL Server]A network-related or instance-specific error has occurred while establishing a connection to SQL Server. Server is not found or not accessible. Check if instance name is correct and if SQL Server is configured to allow remote connections. For more information see SQL Server Books Online. (53)')
(Background on this error at: https://sqlalche.me/e/20/e3q8)
2025-09-04 10:06:03,488 - INFO - Iniciando carga de datos desde 'data\hired_employees.csv' a la tabla 'hired_employees'...
2025-09-04 10:06:19,629 - ERROR - Error fatal durante la carga de datos en 'hired_employees': (pyodbc.OperationalError) ('08001', '[08001] [Microsoft][ODBC Driver 17 for SQL Server]Named Pipes Provider: Could not open a connection to SQL Server [53].  (53) (SQLDriverConnect); [08001] [Microsoft][ODBC Driver 17 for SQL Server]Login timeout expired (0); [08001] [Microsoft][ODBC Driver 17 for SQL Server]A network-related or instance-specific error has occurred while establishing a connection to SQL Server. Server is not found or not accessible. Check if instance name is correct and if SQL Server is configured to allow remote connections. For more information see SQL Server Books Online. (53)')
(Background on this error at: https://sqlalche.me/e/20/e3q8)
Traceback (most recent call last):
  File "C:\Users\User\Desktop\Pruebas_Lab\Prueba_Jikk\.venv\Lib\site-packages\sqlalchemy\engine\base.py", line 143, in __init__
    self._dbapi_connection = engine.raw_connection()
                             ~~~~~~~~~~~~~~~~~~~~~^^
  File "C:\Users\User\Desktop\Pruebas_Lab\Prueba_Jikk\.venv\Lib\site-packages\sqlalchemy\engine\base.py", line 3301, in raw_connection
    return self.pool.connect()
           ~~~~~~~~~~~~~~~~~^^
  File "C:\Users\User\Desktop\Pruebas_Lab\Prueba_Jikk\.venv\Lib\site-packages\sqlalchemy\pool\base.py", line 447, in connect
    return _ConnectionFairy._checkout(self)
           ~~~~~~~~~~~~~~~~~~~~~~~~~~^^^^^^
  File "C:\Users\User\Desktop\Pruebas_Lab\Prueba_Jikk\.venv\Lib\site-packages\sqlalchemy\pool\base.py", line 1264, in _checkout
    fairy = _ConnectionRecord.checkout(pool)
  File "C:\Users\User\Desktop\Pruebas_Lab\Prueba_Jikk\.venv\Lib\site-packages\sqlalchemy\pool\base.py", line 711, in checkout
    rec = pool._do_get()
  File "C:\Users\User\Desktop\Pruebas_Lab\Prueba_Jikk\.venv\Lib\site-packages\sqlalchemy\pool\impl.py", line 177, in _do_get
    with util.safe_reraise():
         ~~~~~~~~~~~~~~~~~^^
  File "C:\Users\User\Desktop\Pruebas_Lab\Prueba_Jikk\.venv\Lib\site-packages\sqlalchemy\util\langhelpers.py", line 224, in __exit__
    raise exc_value.with_traceback(exc_tb)
  File "C:\Users\User\Desktop\Pruebas_Lab\Prueba_Jikk\.venv\Lib\site-packages\sqlalchemy\pool\impl.py", line 175, in _do_get
    return self._create_connection()
           ~~~~~~~~~~~~~~~~~~~~~~~^^
  File "C:\Users\User\Desktop\Pruebas_Lab\Prueba_Jikk\.venv\Lib\site-packages\sqlalchemy\pool\base.py", line 388, in _create_connection
    return _ConnectionRecord(self)
  File "C:\Users\User\Desktop\Pruebas_Lab\Prueba_Jikk\.venv\Lib\site-packages\sqlalchemy\pool\base.py", line 673, in __init__
    self.__connect()
    ~~~~~~~~~~~~~~^^
  File "C:\Users\User\Desktop\Pruebas_Lab\Prueba_Jikk\.venv\Lib\site-packages\sqlalchemy\pool\base.py", line 899, in __connect
    with util.safe_reraise():
         ~~~~~~~~~~~~~~~~~^^
  File "C:\Users\User\Desktop\Pruebas_Lab\Prueba_Jikk\.venv\Lib\site-packages\sqlalchemy\util\langhelpers.py", line 224, in __exit__
    raise exc_value.with_traceback(exc_tb)
  File "C:\Users\User\Desktop\Pruebas_Lab\Prueba_Jikk\.venv\Lib\site-packages\sqlalchemy\pool\base.py", line 895, in __connect
    self.dbapi_connection = connection = pool._invoke_creator(self)
                                         ~~~~~~~~~~~~~~~~~~~~^^^^^^
  File "C:\Users\User\Desktop\Pruebas_Lab\Prueba_Jikk\.venv\Lib\site-packages\sqlalchemy\engine\create.py", line 661, in connect
    return dialect.connect(*cargs, **cparams)
           ~~~~~~~~~~~~~~~^^^^^^^^^^^^^^^^^^^
  File "C:\Users\User\Desktop\Pruebas_Lab\Prueba_Jikk\.venv\Lib\site-packages\sqlalchemy\engine\default.py", line 629, in connect
    return self.loaded_dbapi.connect(*cargs, **cparams)  # type: ignore[no-any-return]  # NOQA: E501
           ~~~~~~~~~~~~~~~~~~~~~~~~~^^^^^^^^^^^^^^^^^^^
pyodbc.OperationalError: ('08001', '[08001] [Microsoft][ODBC Driver 17 for SQL Server]Named Pipes Provider: Could not open a connection to SQL Server [53].  (53) (SQLDriverConnect); [08001] [Microsoft][ODBC Driver 17 for SQL Server]Login timeout expired (0); [08001] [Microsoft][ODBC Driver 17 for SQL Server]A network-related or instance-specific error has occurred while establishing a connection to SQL Server. Server is not found or not accessible. Check if instance name is correct and if SQL Server is configured to allow remote connections. For more information see SQL Server Books Online. (53)')

The above exception was the direct cause of the following exception:

Traceback (most recent call last):
  File "c:\Users\User\Desktop\Pruebas_Lab\Prueba_Jikk\historico.py", line 38, in load_data_from_csv
    chunk.to_sql(table_name, con=engine, if_exists='append', index=False)
    ~~~~~~~~~~~~^^^^^^^^^^^^^^^^^^^^^^^^^^^^^^^^^^^^^^^^^^^^^^^^^^^^^^^^^
  File "C:\Users\User\Desktop\Pruebas_Lab\Prueba_Jikk\.venv\Lib\site-packages\pandas\util\_decorators.py", line 333, in wrapper
    return func(*args, **kwargs)
  File "C:\Users\User\Desktop\Pruebas_Lab\Prueba_Jikk\.venv\Lib\site-packages\pandas\core\generic.py", line 3106, in to_sql
    return sql.to_sql(
           ~~~~~~~~~~^
        self,
        ^^^^^
    ...<8 lines>...
        method=method,
        ^^^^^^^^^^^^^^
    )
    ^
  File "C:\Users\User\Desktop\Pruebas_Lab\Prueba_Jikk\.venv\Lib\site-packages\pandas\io\sql.py", line 843, in to_sql
    with pandasSQL_builder(con, schema=schema, need_transaction=True) as pandas_sql:
         ~~~~~~~~~~~~~~~~~^^^^^^^^^^^^^^^^^^^^^^^^^^^^^^^^^^^^^^^^^^^
  File "C:\Users\User\Desktop\Pruebas_Lab\Prueba_Jikk\.venv\Lib\site-packages\pandas\io\sql.py", line 908, in pandasSQL_builder
    return SQLDatabase(con, schema, need_transaction)
  File "C:\Users\User\Desktop\Pruebas_Lab\Prueba_Jikk\.venv\Lib\site-packages\pandas\io\sql.py", line 1648, in __init__
    con = self.exit_stack.enter_context(con.connect())
                                        ~~~~~~~~~~~^^
  File "C:\Users\User\Desktop\Pruebas_Lab\Prueba_Jikk\.venv\Lib\site-packages\sqlalchemy\engine\base.py", line 3277, in connect
    return self._connection_cls(self)
           ~~~~~~~~~~~~~~~~~~~~^^^^^^
  File "C:\Users\User\Desktop\Pruebas_Lab\Prueba_Jikk\.venv\Lib\site-packages\sqlalchemy\engine\base.py", line 145, in __init__
    Connection._handle_dbapi_exception_noconnection(
    ~~~~~~~~~~~~~~~~~~~~~~~~~~~~~~~~~~~~~~~~~~~~~~~^
        err, dialect, engine
        ^^^^^^^^^^^^^^^^^^^^
    )
    ^
  File "C:\Users\User\Desktop\Pruebas_Lab\Prueba_Jikk\.venv\Lib\site-packages\sqlalchemy\engine\base.py", line 2440, in _handle_dbapi_exception_noconnection
    raise sqlalchemy_exception.with_traceback(exc_info[2]) from e
  File "C:\Users\User\Desktop\Pruebas_Lab\Prueba_Jikk\.venv\Lib\site-packages\sqlalchemy\engine\base.py", line 143, in __init__
    self._dbapi_connection = engine.raw_connection()
                             ~~~~~~~~~~~~~~~~~~~~~^^
  File "C:\Users\User\Desktop\Pruebas_Lab\Prueba_Jikk\.venv\Lib\site-packages\sqlalchemy\engine\base.py", line 3301, in raw_connection
    return self.pool.connect()
           ~~~~~~~~~~~~~~~~~^^
  File "C:\Users\User\Desktop\Pruebas_Lab\Prueba_Jikk\.venv\Lib\site-packages\sqlalchemy\pool\base.py", line 447, in connect
    return _ConnectionFairy._checkout(self)
           ~~~~~~~~~~~~~~~~~~~~~~~~~~^^^^^^
  File "C:\Users\User\Desktop\Pruebas_Lab\Prueba_Jikk\.venv\Lib\site-packages\sqlalchemy\pool\base.py", line 1264, in _checkout
    fairy = _ConnectionRecord.checkout(pool)
  File "C:\Users\User\Desktop\Pruebas_Lab\Prueba_Jikk\.venv\Lib\site-packages\sqlalchemy\pool\base.py", line 711, in checkout
    rec = pool._do_get()
  File "C:\Users\User\Desktop\Pruebas_Lab\Prueba_Jikk\.venv\Lib\site-packages\sqlalchemy\pool\impl.py", line 177, in _do_get
    with util.safe_reraise():
         ~~~~~~~~~~~~~~~~~^^
  File "C:\Users\User\Desktop\Pruebas_Lab\Prueba_Jikk\.venv\Lib\site-packages\sqlalchemy\util\langhelpers.py", line 224, in __exit__
    raise exc_value.with_traceback(exc_tb)
  File "C:\Users\User\Desktop\Pruebas_Lab\Prueba_Jikk\.venv\Lib\site-packages\sqlalchemy\pool\impl.py", line 175, in _do_get
    return self._create_connection()
           ~~~~~~~~~~~~~~~~~~~~~~~^^
  File "C:\Users\User\Desktop\Pruebas_Lab\Prueba_Jikk\.venv\Lib\site-packages\sqlalchemy\pool\base.py", line 388, in _create_connection
    return _ConnectionRecord(self)
  File "C:\Users\User\Desktop\Pruebas_Lab\Prueba_Jikk\.venv\Lib\site-packages\sqlalchemy\pool\base.py", line 673, in __init__
    self.__connect()
    ~~~~~~~~~~~~~~^^
  File "C:\Users\User\Desktop\Pruebas_Lab\Prueba_Jikk\.venv\Lib\site-packages\sqlalchemy\pool\base.py", line 899, in __connect
    with util.safe_reraise():
         ~~~~~~~~~~~~~~~~~^^
  File "C:\Users\User\Desktop\Pruebas_Lab\Prueba_Jikk\.venv\Lib\site-packages\sqlalchemy\util\langhelpers.py", line 224, in __exit__
    raise exc_value.with_traceback(exc_tb)
  File "C:\Users\User\Desktop\Pruebas_Lab\Prueba_Jikk\.venv\Lib\site-packages\sqlalchemy\pool\base.py", line 895, in __connect
    self.dbapi_connection = connection = pool._invoke_creator(self)
                                         ~~~~~~~~~~~~~~~~~~~~^^^^^^
  File "C:\Users\User\Desktop\Pruebas_Lab\Prueba_Jikk\.venv\Lib\site-packages\sqlalchemy\engine\create.py", line 661, in connect
    return dialect.connect(*cargs, **cparams)
           ~~~~~~~~~~~~~~~^^^^^^^^^^^^^^^^^^^
  File "C:\Users\User\Desktop\Pruebas_Lab\Prueba_Jikk\.venv\Lib\site-packages\sqlalchemy\engine\default.py", line 629, in connect
    return self.loaded_dbapi.connect(*cargs, **cparams)  # type: ignore[no-any-return]  # NOQA: E501
           ~~~~~~~~~~~~~~~~~~~~~~~~~^^^^^^^^^^^^^^^^^^^
sqlalchemy.exc.OperationalError: (pyodbc.OperationalError) ('08001', '[08001] [Microsoft][ODBC Driver 17 for SQL Server]Named Pipes Provider: Could not open a connection to SQL Server [53].  (53) (SQLDriverConnect); [08001] [Microsoft][ODBC Driver 17 for SQL Server]Login timeout expired (0); [08001] [Microsoft][ODBC Driver 17 for SQL Server]A network-related or instance-specific error has occurred while establishing a connection to SQL Server. Server is not found or not accessible. Check if instance name is correct and if SQL Server is configured to allow remote connections. For more information see SQL Server Books Online. (53)')
(Background on this error at: https://sqlalche.me/e/20/e3q8)
2025-09-04 10:07:19,025 - INFO - Iniciando carga de datos desde 'data\departments.csv' a la tabla 'departments'...
2025-09-04 10:07:35,622 - ERROR - Error fatal durante la carga de datos en 'departments': (pyodbc.OperationalError) ('08001', '[08001] [Microsoft][ODBC Driver 17 for SQL Server]Named Pipes Provider: Could not open a connection to SQL Server [53].  (53) (SQLDriverConnect); [08001] [Microsoft][ODBC Driver 17 for SQL Server]Login timeout expired (0); [08001] [Microsoft][ODBC Driver 17 for SQL Server]A network-related or instance-specific error has occurred while establishing a connection to SQL Server. Server is not found or not accessible. Check if instance name is correct and if SQL Server is configured to allow remote connections. For more information see SQL Server Books Online. (53)')
(Background on this error at: https://sqlalche.me/e/20/e3q8)
Traceback (most recent call last):
  File "C:\Users\User\Desktop\Pruebas_Lab\Prueba_Jikk\.venv\Lib\site-packages\sqlalchemy\engine\base.py", line 143, in __init__
    self._dbapi_connection = engine.raw_connection()
                             ~~~~~~~~~~~~~~~~~~~~~^^
  File "C:\Users\User\Desktop\Pruebas_Lab\Prueba_Jikk\.venv\Lib\site-packages\sqlalchemy\engine\base.py", line 3301, in raw_connection
    return self.pool.connect()
           ~~~~~~~~~~~~~~~~~^^
  File "C:\Users\User\Desktop\Pruebas_Lab\Prueba_Jikk\.venv\Lib\site-packages\sqlalchemy\pool\base.py", line 447, in connect
    return _ConnectionFairy._checkout(self)
           ~~~~~~~~~~~~~~~~~~~~~~~~~~^^^^^^
  File "C:\Users\User\Desktop\Pruebas_Lab\Prueba_Jikk\.venv\Lib\site-packages\sqlalchemy\pool\base.py", line 1264, in _checkout
    fairy = _ConnectionRecord.checkout(pool)
  File "C:\Users\User\Desktop\Pruebas_Lab\Prueba_Jikk\.venv\Lib\site-packages\sqlalchemy\pool\base.py", line 711, in checkout
    rec = pool._do_get()
  File "C:\Users\User\Desktop\Pruebas_Lab\Prueba_Jikk\.venv\Lib\site-packages\sqlalchemy\pool\impl.py", line 177, in _do_get
    with util.safe_reraise():
         ~~~~~~~~~~~~~~~~~^^
  File "C:\Users\User\Desktop\Pruebas_Lab\Prueba_Jikk\.venv\Lib\site-packages\sqlalchemy\util\langhelpers.py", line 224, in __exit__
    raise exc_value.with_traceback(exc_tb)
  File "C:\Users\User\Desktop\Pruebas_Lab\Prueba_Jikk\.venv\Lib\site-packages\sqlalchemy\pool\impl.py", line 175, in _do_get
    return self._create_connection()
           ~~~~~~~~~~~~~~~~~~~~~~~^^
  File "C:\Users\User\Desktop\Pruebas_Lab\Prueba_Jikk\.venv\Lib\site-packages\sqlalchemy\pool\base.py", line 388, in _create_connection
    return _ConnectionRecord(self)
  File "C:\Users\User\Desktop\Pruebas_Lab\Prueba_Jikk\.venv\Lib\site-packages\sqlalchemy\pool\base.py", line 673, in __init__
    self.__connect()
    ~~~~~~~~~~~~~~^^
  File "C:\Users\User\Desktop\Pruebas_Lab\Prueba_Jikk\.venv\Lib\site-packages\sqlalchemy\pool\base.py", line 899, in __connect
    with util.safe_reraise():
         ~~~~~~~~~~~~~~~~~^^
  File "C:\Users\User\Desktop\Pruebas_Lab\Prueba_Jikk\.venv\Lib\site-packages\sqlalchemy\util\langhelpers.py", line 224, in __exit__
    raise exc_value.with_traceback(exc_tb)
  File "C:\Users\User\Desktop\Pruebas_Lab\Prueba_Jikk\.venv\Lib\site-packages\sqlalchemy\pool\base.py", line 895, in __connect
    self.dbapi_connection = connection = pool._invoke_creator(self)
                                         ~~~~~~~~~~~~~~~~~~~~^^^^^^
  File "C:\Users\User\Desktop\Pruebas_Lab\Prueba_Jikk\.venv\Lib\site-packages\sqlalchemy\engine\create.py", line 661, in connect
    return dialect.connect(*cargs, **cparams)
           ~~~~~~~~~~~~~~~^^^^^^^^^^^^^^^^^^^
  File "C:\Users\User\Desktop\Pruebas_Lab\Prueba_Jikk\.venv\Lib\site-packages\sqlalchemy\engine\default.py", line 629, in connect
    return self.loaded_dbapi.connect(*cargs, **cparams)  # type: ignore[no-any-return]  # NOQA: E501
           ~~~~~~~~~~~~~~~~~~~~~~~~~^^^^^^^^^^^^^^^^^^^
pyodbc.OperationalError: ('08001', '[08001] [Microsoft][ODBC Driver 17 for SQL Server]Named Pipes Provider: Could not open a connection to SQL Server [53].  (53) (SQLDriverConnect); [08001] [Microsoft][ODBC Driver 17 for SQL Server]Login timeout expired (0); [08001] [Microsoft][ODBC Driver 17 for SQL Server]A network-related or instance-specific error has occurred while establishing a connection to SQL Server. Server is not found or not accessible. Check if instance name is correct and if SQL Server is configured to allow remote connections. For more information see SQL Server Books Online. (53)')

The above exception was the direct cause of the following exception:

Traceback (most recent call last):
  File "c:\Users\User\Desktop\Pruebas_Lab\Prueba_Jikk\historico.py", line 38, in load_data_from_csv
    chunk.to_sql(table_name, con=engine, if_exists='append', index=False)
    ~~~~~~~~~~~~^^^^^^^^^^^^^^^^^^^^^^^^^^^^^^^^^^^^^^^^^^^^^^^^^^^^^^^^^
  File "C:\Users\User\Desktop\Pruebas_Lab\Prueba_Jikk\.venv\Lib\site-packages\pandas\util\_decorators.py", line 333, in wrapper
    return func(*args, **kwargs)
  File "C:\Users\User\Desktop\Pruebas_Lab\Prueba_Jikk\.venv\Lib\site-packages\pandas\core\generic.py", line 3106, in to_sql
    return sql.to_sql(
           ~~~~~~~~~~^
        self,
        ^^^^^
    ...<8 lines>...
        method=method,
        ^^^^^^^^^^^^^^
    )
    ^
  File "C:\Users\User\Desktop\Pruebas_Lab\Prueba_Jikk\.venv\Lib\site-packages\pandas\io\sql.py", line 843, in to_sql
    with pandasSQL_builder(con, schema=schema, need_transaction=True) as pandas_sql:
         ~~~~~~~~~~~~~~~~~^^^^^^^^^^^^^^^^^^^^^^^^^^^^^^^^^^^^^^^^^^^
  File "C:\Users\User\Desktop\Pruebas_Lab\Prueba_Jikk\.venv\Lib\site-packages\pandas\io\sql.py", line 908, in pandasSQL_builder
    return SQLDatabase(con, schema, need_transaction)
  File "C:\Users\User\Desktop\Pruebas_Lab\Prueba_Jikk\.venv\Lib\site-packages\pandas\io\sql.py", line 1648, in __init__
    con = self.exit_stack.enter_context(con.connect())
                                        ~~~~~~~~~~~^^
  File "C:\Users\User\Desktop\Pruebas_Lab\Prueba_Jikk\.venv\Lib\site-packages\sqlalchemy\engine\base.py", line 3277, in connect
    return self._connection_cls(self)
           ~~~~~~~~~~~~~~~~~~~~^^^^^^
  File "C:\Users\User\Desktop\Pruebas_Lab\Prueba_Jikk\.venv\Lib\site-packages\sqlalchemy\engine\base.py", line 145, in __init__
    Connection._handle_dbapi_exception_noconnection(
    ~~~~~~~~~~~~~~~~~~~~~~~~~~~~~~~~~~~~~~~~~~~~~~~^
        err, dialect, engine
        ^^^^^^^^^^^^^^^^^^^^
    )
    ^
  File "C:\Users\User\Desktop\Pruebas_Lab\Prueba_Jikk\.venv\Lib\site-packages\sqlalchemy\engine\base.py", line 2440, in _handle_dbapi_exception_noconnection
    raise sqlalchemy_exception.with_traceback(exc_info[2]) from e
  File "C:\Users\User\Desktop\Pruebas_Lab\Prueba_Jikk\.venv\Lib\site-packages\sqlalchemy\engine\base.py", line 143, in __init__
    self._dbapi_connection = engine.raw_connection()
                             ~~~~~~~~~~~~~~~~~~~~~^^
  File "C:\Users\User\Desktop\Pruebas_Lab\Prueba_Jikk\.venv\Lib\site-packages\sqlalchemy\engine\base.py", line 3301, in raw_connection
    return self.pool.connect()
           ~~~~~~~~~~~~~~~~~^^
  File "C:\Users\User\Desktop\Pruebas_Lab\Prueba_Jikk\.venv\Lib\site-packages\sqlalchemy\pool\base.py", line 447, in connect
    return _ConnectionFairy._checkout(self)
           ~~~~~~~~~~~~~~~~~~~~~~~~~~^^^^^^
  File "C:\Users\User\Desktop\Pruebas_Lab\Prueba_Jikk\.venv\Lib\site-packages\sqlalchemy\pool\base.py", line 1264, in _checkout
    fairy = _ConnectionRecord.checkout(pool)
  File "C:\Users\User\Desktop\Pruebas_Lab\Prueba_Jikk\.venv\Lib\site-packages\sqlalchemy\pool\base.py", line 711, in checkout
    rec = pool._do_get()
  File "C:\Users\User\Desktop\Pruebas_Lab\Prueba_Jikk\.venv\Lib\site-packages\sqlalchemy\pool\impl.py", line 177, in _do_get
    with util.safe_reraise():
         ~~~~~~~~~~~~~~~~~^^
  File "C:\Users\User\Desktop\Pruebas_Lab\Prueba_Jikk\.venv\Lib\site-packages\sqlalchemy\util\langhelpers.py", line 224, in __exit__
    raise exc_value.with_traceback(exc_tb)
  File "C:\Users\User\Desktop\Pruebas_Lab\Prueba_Jikk\.venv\Lib\site-packages\sqlalchemy\pool\impl.py", line 175, in _do_get
    return self._create_connection()
           ~~~~~~~~~~~~~~~~~~~~~~~^^
  File "C:\Users\User\Desktop\Pruebas_Lab\Prueba_Jikk\.venv\Lib\site-packages\sqlalchemy\pool\base.py", line 388, in _create_connection
    return _ConnectionRecord(self)
  File "C:\Users\User\Desktop\Pruebas_Lab\Prueba_Jikk\.venv\Lib\site-packages\sqlalchemy\pool\base.py", line 673, in __init__
    self.__connect()
    ~~~~~~~~~~~~~~^^
  File "C:\Users\User\Desktop\Pruebas_Lab\Prueba_Jikk\.venv\Lib\site-packages\sqlalchemy\pool\base.py", line 899, in __connect
    with util.safe_reraise():
         ~~~~~~~~~~~~~~~~~^^
  File "C:\Users\User\Desktop\Pruebas_Lab\Prueba_Jikk\.venv\Lib\site-packages\sqlalchemy\util\langhelpers.py", line 224, in __exit__
    raise exc_value.with_traceback(exc_tb)
  File "C:\Users\User\Desktop\Pruebas_Lab\Prueba_Jikk\.venv\Lib\site-packages\sqlalchemy\pool\base.py", line 895, in __connect
    self.dbapi_connection = connection = pool._invoke_creator(self)
                                         ~~~~~~~~~~~~~~~~~~~~^^^^^^
  File "C:\Users\User\Desktop\Pruebas_Lab\Prueba_Jikk\.venv\Lib\site-packages\sqlalchemy\engine\create.py", line 661, in connect
    return dialect.connect(*cargs, **cparams)
           ~~~~~~~~~~~~~~~^^^^^^^^^^^^^^^^^^^
  File "C:\Users\User\Desktop\Pruebas_Lab\Prueba_Jikk\.venv\Lib\site-packages\sqlalchemy\engine\default.py", line 629, in connect
    return self.loaded_dbapi.connect(*cargs, **cparams)  # type: ignore[no-any-return]  # NOQA: E501
           ~~~~~~~~~~~~~~~~~~~~~~~~~^^^^^^^^^^^^^^^^^^^
sqlalchemy.exc.OperationalError: (pyodbc.OperationalError) ('08001', '[08001] [Microsoft][ODBC Driver 17 for SQL Server]Named Pipes Provider: Could not open a connection to SQL Server [53].  (53) (SQLDriverConnect); [08001] [Microsoft][ODBC Driver 17 for SQL Server]Login timeout expired (0); [08001] [Microsoft][ODBC Driver 17 for SQL Server]A network-related or instance-specific error has occurred while establishing a connection to SQL Server. Server is not found or not accessible. Check if instance name is correct and if SQL Server is configured to allow remote connections. For more information see SQL Server Books Online. (53)')
(Background on this error at: https://sqlalche.me/e/20/e3q8)
2025-09-04 10:07:35,634 - INFO - Iniciando carga de datos desde 'data\jobs.csv' a la tabla 'jobs'...
2025-09-04 10:07:52,778 - ERROR - Error fatal durante la carga de datos en 'jobs': (pyodbc.OperationalError) ('08001', '[08001] [Microsoft][ODBC Driver 17 for SQL Server]Named Pipes Provider: Could not open a connection to SQL Server [53].  (53) (SQLDriverConnect); [08001] [Microsoft][ODBC Driver 17 for SQL Server]Login timeout expired (0); [08001] [Microsoft][ODBC Driver 17 for SQL Server]A network-related or instance-specific error has occurred while establishing a connection to SQL Server. Server is not found or not accessible. Check if instance name is correct and if SQL Server is configured to allow remote connections. For more information see SQL Server Books Online. (53)')
(Background on this error at: https://sqlalche.me/e/20/e3q8)
Traceback (most recent call last):
  File "C:\Users\User\Desktop\Pruebas_Lab\Prueba_Jikk\.venv\Lib\site-packages\sqlalchemy\engine\base.py", line 143, in __init__
    self._dbapi_connection = engine.raw_connection()
                             ~~~~~~~~~~~~~~~~~~~~~^^
  File "C:\Users\User\Desktop\Pruebas_Lab\Prueba_Jikk\.venv\Lib\site-packages\sqlalchemy\engine\base.py", line 3301, in raw_connection
    return self.pool.connect()
           ~~~~~~~~~~~~~~~~~^^
  File "C:\Users\User\Desktop\Pruebas_Lab\Prueba_Jikk\.venv\Lib\site-packages\sqlalchemy\pool\base.py", line 447, in connect
    return _ConnectionFairy._checkout(self)
           ~~~~~~~~~~~~~~~~~~~~~~~~~~^^^^^^
  File "C:\Users\User\Desktop\Pruebas_Lab\Prueba_Jikk\.venv\Lib\site-packages\sqlalchemy\pool\base.py", line 1264, in _checkout
    fairy = _ConnectionRecord.checkout(pool)
  File "C:\Users\User\Desktop\Pruebas_Lab\Prueba_Jikk\.venv\Lib\site-packages\sqlalchemy\pool\base.py", line 711, in checkout
    rec = pool._do_get()
  File "C:\Users\User\Desktop\Pruebas_Lab\Prueba_Jikk\.venv\Lib\site-packages\sqlalchemy\pool\impl.py", line 177, in _do_get
    with util.safe_reraise():
         ~~~~~~~~~~~~~~~~~^^
  File "C:\Users\User\Desktop\Pruebas_Lab\Prueba_Jikk\.venv\Lib\site-packages\sqlalchemy\util\langhelpers.py", line 224, in __exit__
    raise exc_value.with_traceback(exc_tb)
  File "C:\Users\User\Desktop\Pruebas_Lab\Prueba_Jikk\.venv\Lib\site-packages\sqlalchemy\pool\impl.py", line 175, in _do_get
    return self._create_connection()
           ~~~~~~~~~~~~~~~~~~~~~~~^^
  File "C:\Users\User\Desktop\Pruebas_Lab\Prueba_Jikk\.venv\Lib\site-packages\sqlalchemy\pool\base.py", line 388, in _create_connection
    return _ConnectionRecord(self)
  File "C:\Users\User\Desktop\Pruebas_Lab\Prueba_Jikk\.venv\Lib\site-packages\sqlalchemy\pool\base.py", line 673, in __init__
    self.__connect()
    ~~~~~~~~~~~~~~^^
  File "C:\Users\User\Desktop\Pruebas_Lab\Prueba_Jikk\.venv\Lib\site-packages\sqlalchemy\pool\base.py", line 899, in __connect
    with util.safe_reraise():
         ~~~~~~~~~~~~~~~~~^^
  File "C:\Users\User\Desktop\Pruebas_Lab\Prueba_Jikk\.venv\Lib\site-packages\sqlalchemy\util\langhelpers.py", line 224, in __exit__
    raise exc_value.with_traceback(exc_tb)
  File "C:\Users\User\Desktop\Pruebas_Lab\Prueba_Jikk\.venv\Lib\site-packages\sqlalchemy\pool\base.py", line 895, in __connect
    self.dbapi_connection = connection = pool._invoke_creator(self)
                                         ~~~~~~~~~~~~~~~~~~~~^^^^^^
  File "C:\Users\User\Desktop\Pruebas_Lab\Prueba_Jikk\.venv\Lib\site-packages\sqlalchemy\engine\create.py", line 661, in connect
    return dialect.connect(*cargs, **cparams)
           ~~~~~~~~~~~~~~~^^^^^^^^^^^^^^^^^^^
  File "C:\Users\User\Desktop\Pruebas_Lab\Prueba_Jikk\.venv\Lib\site-packages\sqlalchemy\engine\default.py", line 629, in connect
    return self.loaded_dbapi.connect(*cargs, **cparams)  # type: ignore[no-any-return]  # NOQA: E501
           ~~~~~~~~~~~~~~~~~~~~~~~~~^^^^^^^^^^^^^^^^^^^
pyodbc.OperationalError: ('08001', '[08001] [Microsoft][ODBC Driver 17 for SQL Server]Named Pipes Provider: Could not open a connection to SQL Server [53].  (53) (SQLDriverConnect); [08001] [Microsoft][ODBC Driver 17 for SQL Server]Login timeout expired (0); [08001] [Microsoft][ODBC Driver 17 for SQL Server]A network-related or instance-specific error has occurred while establishing a connection to SQL Server. Server is not found or not accessible. Check if instance name is correct and if SQL Server is configured to allow remote connections. For more information see SQL Server Books Online. (53)')

The above exception was the direct cause of the following exception:

Traceback (most recent call last):
  File "c:\Users\User\Desktop\Pruebas_Lab\Prueba_Jikk\historico.py", line 38, in load_data_from_csv
    chunk.to_sql(table_name, con=engine, if_exists='append', index=False)
    ~~~~~~~~~~~~^^^^^^^^^^^^^^^^^^^^^^^^^^^^^^^^^^^^^^^^^^^^^^^^^^^^^^^^^
  File "C:\Users\User\Desktop\Pruebas_Lab\Prueba_Jikk\.venv\Lib\site-packages\pandas\util\_decorators.py", line 333, in wrapper
    return func(*args, **kwargs)
  File "C:\Users\User\Desktop\Pruebas_Lab\Prueba_Jikk\.venv\Lib\site-packages\pandas\core\generic.py", line 3106, in to_sql
    return sql.to_sql(
           ~~~~~~~~~~^
        self,
        ^^^^^
    ...<8 lines>...
        method=method,
        ^^^^^^^^^^^^^^
    )
    ^
  File "C:\Users\User\Desktop\Pruebas_Lab\Prueba_Jikk\.venv\Lib\site-packages\pandas\io\sql.py", line 843, in to_sql
    with pandasSQL_builder(con, schema=schema, need_transaction=True) as pandas_sql:
         ~~~~~~~~~~~~~~~~~^^^^^^^^^^^^^^^^^^^^^^^^^^^^^^^^^^^^^^^^^^^
  File "C:\Users\User\Desktop\Pruebas_Lab\Prueba_Jikk\.venv\Lib\site-packages\pandas\io\sql.py", line 908, in pandasSQL_builder
    return SQLDatabase(con, schema, need_transaction)
  File "C:\Users\User\Desktop\Pruebas_Lab\Prueba_Jikk\.venv\Lib\site-packages\pandas\io\sql.py", line 1648, in __init__
    con = self.exit_stack.enter_context(con.connect())
                                        ~~~~~~~~~~~^^
  File "C:\Users\User\Desktop\Pruebas_Lab\Prueba_Jikk\.venv\Lib\site-packages\sqlalchemy\engine\base.py", line 3277, in connect
    return self._connection_cls(self)
           ~~~~~~~~~~~~~~~~~~~~^^^^^^
  File "C:\Users\User\Desktop\Pruebas_Lab\Prueba_Jikk\.venv\Lib\site-packages\sqlalchemy\engine\base.py", line 145, in __init__
    Connection._handle_dbapi_exception_noconnection(
    ~~~~~~~~~~~~~~~~~~~~~~~~~~~~~~~~~~~~~~~~~~~~~~~^
        err, dialect, engine
        ^^^^^^^^^^^^^^^^^^^^
    )
    ^
  File "C:\Users\User\Desktop\Pruebas_Lab\Prueba_Jikk\.venv\Lib\site-packages\sqlalchemy\engine\base.py", line 2440, in _handle_dbapi_exception_noconnection
    raise sqlalchemy_exception.with_traceback(exc_info[2]) from e
  File "C:\Users\User\Desktop\Pruebas_Lab\Prueba_Jikk\.venv\Lib\site-packages\sqlalchemy\engine\base.py", line 143, in __init__
    self._dbapi_connection = engine.raw_connection()
                             ~~~~~~~~~~~~~~~~~~~~~^^
  File "C:\Users\User\Desktop\Pruebas_Lab\Prueba_Jikk\.venv\Lib\site-packages\sqlalchemy\engine\base.py", line 3301, in raw_connection
    return self.pool.connect()
           ~~~~~~~~~~~~~~~~~^^
  File "C:\Users\User\Desktop\Pruebas_Lab\Prueba_Jikk\.venv\Lib\site-packages\sqlalchemy\pool\base.py", line 447, in connect
    return _ConnectionFairy._checkout(self)
           ~~~~~~~~~~~~~~~~~~~~~~~~~~^^^^^^
  File "C:\Users\User\Desktop\Pruebas_Lab\Prueba_Jikk\.venv\Lib\site-packages\sqlalchemy\pool\base.py", line 1264, in _checkout
    fairy = _ConnectionRecord.checkout(pool)
  File "C:\Users\User\Desktop\Pruebas_Lab\Prueba_Jikk\.venv\Lib\site-packages\sqlalchemy\pool\base.py", line 711, in checkout
    rec = pool._do_get()
  File "C:\Users\User\Desktop\Pruebas_Lab\Prueba_Jikk\.venv\Lib\site-packages\sqlalchemy\pool\impl.py", line 177, in _do_get
    with util.safe_reraise():
         ~~~~~~~~~~~~~~~~~^^
  File "C:\Users\User\Desktop\Pruebas_Lab\Prueba_Jikk\.venv\Lib\site-packages\sqlalchemy\util\langhelpers.py", line 224, in __exit__
    raise exc_value.with_traceback(exc_tb)
  File "C:\Users\User\Desktop\Pruebas_Lab\Prueba_Jikk\.venv\Lib\site-packages\sqlalchemy\pool\impl.py", line 175, in _do_get
    return self._create_connection()
           ~~~~~~~~~~~~~~~~~~~~~~~^^
  File "C:\Users\User\Desktop\Pruebas_Lab\Prueba_Jikk\.venv\Lib\site-packages\sqlalchemy\pool\base.py", line 388, in _create_connection
    return _ConnectionRecord(self)
  File "C:\Users\User\Desktop\Pruebas_Lab\Prueba_Jikk\.venv\Lib\site-packages\sqlalchemy\pool\base.py", line 673, in __init__
    self.__connect()
    ~~~~~~~~~~~~~~^^
  File "C:\Users\User\Desktop\Pruebas_Lab\Prueba_Jikk\.venv\Lib\site-packages\sqlalchemy\pool\base.py", line 899, in __connect
    with util.safe_reraise():
         ~~~~~~~~~~~~~~~~~^^
  File "C:\Users\User\Desktop\Pruebas_Lab\Prueba_Jikk\.venv\Lib\site-packages\sqlalchemy\util\langhelpers.py", line 224, in __exit__
    raise exc_value.with_traceback(exc_tb)
  File "C:\Users\User\Desktop\Pruebas_Lab\Prueba_Jikk\.venv\Lib\site-packages\sqlalchemy\pool\base.py", line 895, in __connect
    self.dbapi_connection = connection = pool._invoke_creator(self)
                                         ~~~~~~~~~~~~~~~~~~~~^^^^^^
  File "C:\Users\User\Desktop\Pruebas_Lab\Prueba_Jikk\.venv\Lib\site-packages\sqlalchemy\engine\create.py", line 661, in connect
    return dialect.connect(*cargs, **cparams)
           ~~~~~~~~~~~~~~~^^^^^^^^^^^^^^^^^^^
  File "C:\Users\User\Desktop\Pruebas_Lab\Prueba_Jikk\.venv\Lib\site-packages\sqlalchemy\engine\default.py", line 629, in connect
    return self.loaded_dbapi.connect(*cargs, **cparams)  # type: ignore[no-any-return]  # NOQA: E501
           ~~~~~~~~~~~~~~~~~~~~~~~~~^^^^^^^^^^^^^^^^^^^
sqlalchemy.exc.OperationalError: (pyodbc.OperationalError) ('08001', '[08001] [Microsoft][ODBC Driver 17 for SQL Server]Named Pipes Provider: Could not open a connection to SQL Server [53].  (53) (SQLDriverConnect); [08001] [Microsoft][ODBC Driver 17 for SQL Server]Login timeout expired (0); [08001] [Microsoft][ODBC Driver 17 for SQL Server]A network-related or instance-specific error has occurred while establishing a connection to SQL Server. Server is not found or not accessible. Check if instance name is correct and if SQL Server is configured to allow remote connections. For more information see SQL Server Books Online. (53)')
(Background on this error at: https://sqlalche.me/e/20/e3q8)
2025-09-04 10:07:52,785 - INFO - Iniciando carga de datos desde 'data\hired_employees.csv' a la tabla 'hired_employees'...
2025-09-04 10:08:08,934 - ERROR - Error fatal durante la carga de datos en 'hired_employees': (pyodbc.OperationalError) ('08001', '[08001] [Microsoft][ODBC Driver 17 for SQL Server]Named Pipes Provider: Could not open a connection to SQL Server [53].  (53) (SQLDriverConnect); [08001] [Microsoft][ODBC Driver 17 for SQL Server]Login timeout expired (0); [08001] [Microsoft][ODBC Driver 17 for SQL Server]A network-related or instance-specific error has occurred while establishing a connection to SQL Server. Server is not found or not accessible. Check if instance name is correct and if SQL Server is configured to allow remote connections. For more information see SQL Server Books Online. (53)')
(Background on this error at: https://sqlalche.me/e/20/e3q8)
Traceback (most recent call last):
  File "C:\Users\User\Desktop\Pruebas_Lab\Prueba_Jikk\.venv\Lib\site-packages\sqlalchemy\engine\base.py", line 143, in __init__
    self._dbapi_connection = engine.raw_connection()
                             ~~~~~~~~~~~~~~~~~~~~~^^
  File "C:\Users\User\Desktop\Pruebas_Lab\Prueba_Jikk\.venv\Lib\site-packages\sqlalchemy\engine\base.py", line 3301, in raw_connection
    return self.pool.connect()
           ~~~~~~~~~~~~~~~~~^^
  File "C:\Users\User\Desktop\Pruebas_Lab\Prueba_Jikk\.venv\Lib\site-packages\sqlalchemy\pool\base.py", line 447, in connect
    return _ConnectionFairy._checkout(self)
           ~~~~~~~~~~~~~~~~~~~~~~~~~~^^^^^^
  File "C:\Users\User\Desktop\Pruebas_Lab\Prueba_Jikk\.venv\Lib\site-packages\sqlalchemy\pool\base.py", line 1264, in _checkout
    fairy = _ConnectionRecord.checkout(pool)
  File "C:\Users\User\Desktop\Pruebas_Lab\Prueba_Jikk\.venv\Lib\site-packages\sqlalchemy\pool\base.py", line 711, in checkout
    rec = pool._do_get()
  File "C:\Users\User\Desktop\Pruebas_Lab\Prueba_Jikk\.venv\Lib\site-packages\sqlalchemy\pool\impl.py", line 177, in _do_get
    with util.safe_reraise():
         ~~~~~~~~~~~~~~~~~^^
  File "C:\Users\User\Desktop\Pruebas_Lab\Prueba_Jikk\.venv\Lib\site-packages\sqlalchemy\util\langhelpers.py", line 224, in __exit__
    raise exc_value.with_traceback(exc_tb)
  File "C:\Users\User\Desktop\Pruebas_Lab\Prueba_Jikk\.venv\Lib\site-packages\sqlalchemy\pool\impl.py", line 175, in _do_get
    return self._create_connection()
           ~~~~~~~~~~~~~~~~~~~~~~~^^
  File "C:\Users\User\Desktop\Pruebas_Lab\Prueba_Jikk\.venv\Lib\site-packages\sqlalchemy\pool\base.py", line 388, in _create_connection
    return _ConnectionRecord(self)
  File "C:\Users\User\Desktop\Pruebas_Lab\Prueba_Jikk\.venv\Lib\site-packages\sqlalchemy\pool\base.py", line 673, in __init__
    self.__connect()
    ~~~~~~~~~~~~~~^^
  File "C:\Users\User\Desktop\Pruebas_Lab\Prueba_Jikk\.venv\Lib\site-packages\sqlalchemy\pool\base.py", line 899, in __connect
    with util.safe_reraise():
         ~~~~~~~~~~~~~~~~~^^
  File "C:\Users\User\Desktop\Pruebas_Lab\Prueba_Jikk\.venv\Lib\site-packages\sqlalchemy\util\langhelpers.py", line 224, in __exit__
    raise exc_value.with_traceback(exc_tb)
  File "C:\Users\User\Desktop\Pruebas_Lab\Prueba_Jikk\.venv\Lib\site-packages\sqlalchemy\pool\base.py", line 895, in __connect
    self.dbapi_connection = connection = pool._invoke_creator(self)
                                         ~~~~~~~~~~~~~~~~~~~~^^^^^^
  File "C:\Users\User\Desktop\Pruebas_Lab\Prueba_Jikk\.venv\Lib\site-packages\sqlalchemy\engine\create.py", line 661, in connect
    return dialect.connect(*cargs, **cparams)
           ~~~~~~~~~~~~~~~^^^^^^^^^^^^^^^^^^^
  File "C:\Users\User\Desktop\Pruebas_Lab\Prueba_Jikk\.venv\Lib\site-packages\sqlalchemy\engine\default.py", line 629, in connect
    return self.loaded_dbapi.connect(*cargs, **cparams)  # type: ignore[no-any-return]  # NOQA: E501
           ~~~~~~~~~~~~~~~~~~~~~~~~~^^^^^^^^^^^^^^^^^^^
pyodbc.OperationalError: ('08001', '[08001] [Microsoft][ODBC Driver 17 for SQL Server]Named Pipes Provider: Could not open a connection to SQL Server [53].  (53) (SQLDriverConnect); [08001] [Microsoft][ODBC Driver 17 for SQL Server]Login timeout expired (0); [08001] [Microsoft][ODBC Driver 17 for SQL Server]A network-related or instance-specific error has occurred while establishing a connection to SQL Server. Server is not found or not accessible. Check if instance name is correct and if SQL Server is configured to allow remote connections. For more information see SQL Server Books Online. (53)')

The above exception was the direct cause of the following exception:

Traceback (most recent call last):
  File "c:\Users\User\Desktop\Pruebas_Lab\Prueba_Jikk\historico.py", line 38, in load_data_from_csv
    chunk.to_sql(table_name, con=engine, if_exists='append', index=False)
    ~~~~~~~~~~~~^^^^^^^^^^^^^^^^^^^^^^^^^^^^^^^^^^^^^^^^^^^^^^^^^^^^^^^^^
  File "C:\Users\User\Desktop\Pruebas_Lab\Prueba_Jikk\.venv\Lib\site-packages\pandas\util\_decorators.py", line 333, in wrapper
    return func(*args, **kwargs)
  File "C:\Users\User\Desktop\Pruebas_Lab\Prueba_Jikk\.venv\Lib\site-packages\pandas\core\generic.py", line 3106, in to_sql
    return sql.to_sql(
           ~~~~~~~~~~^
        self,
        ^^^^^
    ...<8 lines>...
        method=method,
        ^^^^^^^^^^^^^^
    )
    ^
  File "C:\Users\User\Desktop\Pruebas_Lab\Prueba_Jikk\.venv\Lib\site-packages\pandas\io\sql.py", line 843, in to_sql
    with pandasSQL_builder(con, schema=schema, need_transaction=True) as pandas_sql:
         ~~~~~~~~~~~~~~~~~^^^^^^^^^^^^^^^^^^^^^^^^^^^^^^^^^^^^^^^^^^^
  File "C:\Users\User\Desktop\Pruebas_Lab\Prueba_Jikk\.venv\Lib\site-packages\pandas\io\sql.py", line 908, in pandasSQL_builder
    return SQLDatabase(con, schema, need_transaction)
  File "C:\Users\User\Desktop\Pruebas_Lab\Prueba_Jikk\.venv\Lib\site-packages\pandas\io\sql.py", line 1648, in __init__
    con = self.exit_stack.enter_context(con.connect())
                                        ~~~~~~~~~~~^^
  File "C:\Users\User\Desktop\Pruebas_Lab\Prueba_Jikk\.venv\Lib\site-packages\sqlalchemy\engine\base.py", line 3277, in connect
    return self._connection_cls(self)
           ~~~~~~~~~~~~~~~~~~~~^^^^^^
  File "C:\Users\User\Desktop\Pruebas_Lab\Prueba_Jikk\.venv\Lib\site-packages\sqlalchemy\engine\base.py", line 145, in __init__
    Connection._handle_dbapi_exception_noconnection(
    ~~~~~~~~~~~~~~~~~~~~~~~~~~~~~~~~~~~~~~~~~~~~~~~^
        err, dialect, engine
        ^^^^^^^^^^^^^^^^^^^^
    )
    ^
  File "C:\Users\User\Desktop\Pruebas_Lab\Prueba_Jikk\.venv\Lib\site-packages\sqlalchemy\engine\base.py", line 2440, in _handle_dbapi_exception_noconnection
    raise sqlalchemy_exception.with_traceback(exc_info[2]) from e
  File "C:\Users\User\Desktop\Pruebas_Lab\Prueba_Jikk\.venv\Lib\site-packages\sqlalchemy\engine\base.py", line 143, in __init__
    self._dbapi_connection = engine.raw_connection()
                             ~~~~~~~~~~~~~~~~~~~~~^^
  File "C:\Users\User\Desktop\Pruebas_Lab\Prueba_Jikk\.venv\Lib\site-packages\sqlalchemy\engine\base.py", line 3301, in raw_connection
    return self.pool.connect()
           ~~~~~~~~~~~~~~~~~^^
  File "C:\Users\User\Desktop\Pruebas_Lab\Prueba_Jikk\.venv\Lib\site-packages\sqlalchemy\pool\base.py", line 447, in connect
    return _ConnectionFairy._checkout(self)
           ~~~~~~~~~~~~~~~~~~~~~~~~~~^^^^^^
  File "C:\Users\User\Desktop\Pruebas_Lab\Prueba_Jikk\.venv\Lib\site-packages\sqlalchemy\pool\base.py", line 1264, in _checkout
    fairy = _ConnectionRecord.checkout(pool)
  File "C:\Users\User\Desktop\Pruebas_Lab\Prueba_Jikk\.venv\Lib\site-packages\sqlalchemy\pool\base.py", line 711, in checkout
    rec = pool._do_get()
  File "C:\Users\User\Desktop\Pruebas_Lab\Prueba_Jikk\.venv\Lib\site-packages\sqlalchemy\pool\impl.py", line 177, in _do_get
    with util.safe_reraise():
         ~~~~~~~~~~~~~~~~~^^
  File "C:\Users\User\Desktop\Pruebas_Lab\Prueba_Jikk\.venv\Lib\site-packages\sqlalchemy\util\langhelpers.py", line 224, in __exit__
    raise exc_value.with_traceback(exc_tb)
  File "C:\Users\User\Desktop\Pruebas_Lab\Prueba_Jikk\.venv\Lib\site-packages\sqlalchemy\pool\impl.py", line 175, in _do_get
    return self._create_connection()
           ~~~~~~~~~~~~~~~~~~~~~~~^^
  File "C:\Users\User\Desktop\Pruebas_Lab\Prueba_Jikk\.venv\Lib\site-packages\sqlalchemy\pool\base.py", line 388, in _create_connection
    return _ConnectionRecord(self)
  File "C:\Users\User\Desktop\Pruebas_Lab\Prueba_Jikk\.venv\Lib\site-packages\sqlalchemy\pool\base.py", line 673, in __init__
    self.__connect()
    ~~~~~~~~~~~~~~^^
  File "C:\Users\User\Desktop\Pruebas_Lab\Prueba_Jikk\.venv\Lib\site-packages\sqlalchemy\pool\base.py", line 899, in __connect
    with util.safe_reraise():
         ~~~~~~~~~~~~~~~~~^^
  File "C:\Users\User\Desktop\Pruebas_Lab\Prueba_Jikk\.venv\Lib\site-packages\sqlalchemy\util\langhelpers.py", line 224, in __exit__
    raise exc_value.with_traceback(exc_tb)
  File "C:\Users\User\Desktop\Pruebas_Lab\Prueba_Jikk\.venv\Lib\site-packages\sqlalchemy\pool\base.py", line 895, in __connect
    self.dbapi_connection = connection = pool._invoke_creator(self)
                                         ~~~~~~~~~~~~~~~~~~~~^^^^^^
  File "C:\Users\User\Desktop\Pruebas_Lab\Prueba_Jikk\.venv\Lib\site-packages\sqlalchemy\engine\create.py", line 661, in connect
    return dialect.connect(*cargs, **cparams)
           ~~~~~~~~~~~~~~~^^^^^^^^^^^^^^^^^^^
  File "C:\Users\User\Desktop\Pruebas_Lab\Prueba_Jikk\.venv\Lib\site-packages\sqlalchemy\engine\default.py", line 629, in connect
    return self.loaded_dbapi.connect(*cargs, **cparams)  # type: ignore[no-any-return]  # NOQA: E501
           ~~~~~~~~~~~~~~~~~~~~~~~~~^^^^^^^^^^^^^^^^^^^
sqlalchemy.exc.OperationalError: (pyodbc.OperationalError) ('08001', '[08001] [Microsoft][ODBC Driver 17 for SQL Server]Named Pipes Provider: Could not open a connection to SQL Server [53].  (53) (SQLDriverConnect); [08001] [Microsoft][ODBC Driver 17 for SQL Server]Login timeout expired (0); [08001] [Microsoft][ODBC Driver 17 for SQL Server]A network-related or instance-specific error has occurred while establishing a connection to SQL Server. Server is not found or not accessible. Check if instance name is correct and if SQL Server is configured to allow remote connections. For more information see SQL Server Books Online. (53)')
(Background on this error at: https://sqlalche.me/e/20/e3q8)
2025-09-04 10:09:01,963 - WARNING - Fallo conexión con mssql+pyodbc://sa:123@DESKTOP-4MJ4A33\SQLEXPRESS/Prueba_Sep?driver=ODBC+Driver+17+for+SQL+Server: Not an executable object: 'SELECT 1'
2025-09-04 10:09:01,976 - WARNING - Fallo conexión con mssql+pyodbc://sa:123@DESKTOP-4MJ4A33/SQLEXPRESS/Prueba_Sep?driver=ODBC+Driver+17+for+SQL+Server: (pyodbc.InterfaceError) ('28000', '[28000] [Microsoft][ODBC Driver 17 for SQL Server][SQL Server]Login failed for user \'sa\'. (18456) (SQLDriverConnect); [28000] [Microsoft][ODBC Driver 17 for SQL Server][SQL Server]Cannot open database "SQLEXPRESS/Prueba_Sep" requested by the login. The login failed. (4060); [28000] [Microsoft][ODBC Driver 17 for SQL Server][SQL Server]Login failed for user \'sa\'. (18456); [28000] [Microsoft][ODBC Driver 17 for SQL Server][SQL Server]Cannot open database "SQLEXPRESS/Prueba_Sep" requested by the login. The login failed. (4060)')
(Background on this error at: https://sqlalche.me/e/20/rvf5)
2025-09-04 10:09:01,985 - WARNING - Fallo conexión con mssql+pyodbc://sa:123@localhost/SQLEXPRESS/Prueba_Sep?driver=ODBC+Driver+17+for+SQL+Server: (pyodbc.InterfaceError) ('28000', '[28000] [Microsoft][ODBC Driver 17 for SQL Server][SQL Server]Login failed for user \'sa\'. (18456) (SQLDriverConnect); [28000] [Microsoft][ODBC Driver 17 for SQL Server][SQL Server]Cannot open database "SQLEXPRESS/Prueba_Sep" requested by the login. The login failed. (4060); [28000] [Microsoft][ODBC Driver 17 for SQL Server][SQL Server]Login failed for user \'sa\'. (18456); [28000] [Microsoft][ODBC Driver 17 for SQL Server][SQL Server]Cannot open database "SQLEXPRESS/Prueba_Sep" requested by the login. The login failed. (4060)')
(Background on this error at: https://sqlalche.me/e/20/rvf5)
2025-09-04 10:10:05,084 - WARNING - Fallo conexión con mssql+pyodbc://sa:123@DESKTOP-4MJ4A33\SQLEXPRESS/Prueba_Sep?driver=ODBC+Driver+17+for+SQL+Server: Not an executable object: 'SELECT 1'
2025-09-04 10:10:05,092 - WARNING - Fallo conexión con mssql+pyodbc://sa:123@DESKTOP-4MJ4A33/SQLEXPRESS/Prueba_Sep?driver=ODBC+Driver+17+for+SQL+Server: (pyodbc.InterfaceError) ('28000', '[28000] [Microsoft][ODBC Driver 17 for SQL Server][SQL Server]Login failed for user \'sa\'. (18456) (SQLDriverConnect); [28000] [Microsoft][ODBC Driver 17 for SQL Server][SQL Server]Cannot open database "SQLEXPRESS/Prueba_Sep" requested by the login. The login failed. (4060); [28000] [Microsoft][ODBC Driver 17 for SQL Server][SQL Server]Login failed for user \'sa\'. (18456); [28000] [Microsoft][ODBC Driver 17 for SQL Server][SQL Server]Cannot open database "SQLEXPRESS/Prueba_Sep" requested by the login. The login failed. (4060)')
(Background on this error at: https://sqlalche.me/e/20/rvf5)
2025-09-04 10:10:05,101 - WARNING - Fallo conexión con mssql+pyodbc://sa:123@localhost/SQLEXPRESS/Prueba_Sep?driver=ODBC+Driver+17+for+SQL+Server: (pyodbc.InterfaceError) ('28000', '[28000] [Microsoft][ODBC Driver 17 for SQL Server][SQL Server]Login failed for user \'sa\'. (18456) (SQLDriverConnect); [28000] [Microsoft][ODBC Driver 17 for SQL Server][SQL Server]Cannot open database "SQLEXPRESS/Prueba_Sep" requested by the login. The login failed. (4060); [28000] [Microsoft][ODBC Driver 17 for SQL Server][SQL Server]Login failed for user \'sa\'. (18456); [28000] [Microsoft][ODBC Driver 17 for SQL Server][SQL Server]Cannot open database "SQLEXPRESS/Prueba_Sep" requested by the login. The login failed. (4060)')
(Background on this error at: https://sqlalche.me/e/20/rvf5)
2025-09-04 10:31:47,410 - WARNING - Fallo conexión con mssql+pyodbc://sa:123@DESKTOP-4MJ4A33\SQLEXPRESS/Prueba_Sep?driver=ODBC+Driver+17+for+SQL+Server: Not an executable object: 'SELECT 1'
2025-09-04 10:31:47,486 - WARNING - Fallo conexión con mssql+pyodbc://sa:123@DESKTOP-4MJ4A33/SQLEXPRESS/Prueba_Sep?driver=ODBC+Driver+17+for+SQL+Server: (pyodbc.InterfaceError) ('28000', '[28000] [Microsoft][ODBC Driver 17 for SQL Server][SQL Server]Login failed for user \'sa\'. (18456) (SQLDriverConnect); [28000] [Microsoft][ODBC Driver 17 for SQL Server][SQL Server]Cannot open database "SQLEXPRESS/Prueba_Sep" requested by the login. The login failed. (4060); [28000] [Microsoft][ODBC Driver 17 for SQL Server][SQL Server]Login failed for user \'sa\'. (18456); [28000] [Microsoft][ODBC Driver 17 for SQL Server][SQL Server]Cannot open database "SQLEXPRESS/Prueba_Sep" requested by the login. The login failed. (4060)')
(Background on this error at: https://sqlalche.me/e/20/rvf5)
2025-09-04 10:31:47,495 - WARNING - Fallo conexión con mssql+pyodbc://sa:123@localhost/SQLEXPRESS/Prueba_Sep?driver=ODBC+Driver+17+for+SQL+Server: (pyodbc.InterfaceError) ('28000', '[28000] [Microsoft][ODBC Driver 17 for SQL Server][SQL Server]Login failed for user \'sa\'. (18456) (SQLDriverConnect); [28000] [Microsoft][ODBC Driver 17 for SQL Server][SQL Server]Cannot open database "SQLEXPRESS/Prueba_Sep" requested by the login. The login failed. (4060); [28000] [Microsoft][ODBC Driver 17 for SQL Server][SQL Server]Login failed for user \'sa\'. (18456); [28000] [Microsoft][ODBC Driver 17 for SQL Server][SQL Server]Cannot open database "SQLEXPRESS/Prueba_Sep" requested by the login. The login failed. (4060)')
(Background on this error at: https://sqlalche.me/e/20/rvf5)
2025-09-04 10:37:47,215 - WARNING - Fallo conexión con mssql+pyodbc://sa:123@DESKTOP-4MJ4A33\SQLEXPRESS/Prueba_Sep?driver=ODBC+Driver+17+for+SQL+Server: Not an executable object: 'SELECT 1'
2025-09-04 10:37:47,224 - WARNING - Fallo conexión con mssql+pyodbc://sa:123@DESKTOP-4MJ4A33/SQLEXPRESS/Prueba_Sep?driver=ODBC+Driver+17+for+SQL+Server: (pyodbc.InterfaceError) ('28000', '[28000] [Microsoft][ODBC Driver 17 for SQL Server][SQL Server]Login failed for user \'sa\'. (18456) (SQLDriverConnect); [28000] [Microsoft][ODBC Driver 17 for SQL Server][SQL Server]Cannot open database "SQLEXPRESS/Prueba_Sep" requested by the login. The login failed. (4060); [28000] [Microsoft][ODBC Driver 17 for SQL Server][SQL Server]Login failed for user \'sa\'. (18456); [28000] [Microsoft][ODBC Driver 17 for SQL Server][SQL Server]Cannot open database "SQLEXPRESS/Prueba_Sep" requested by the login. The login failed. (4060)')
(Background on this error at: https://sqlalche.me/e/20/rvf5)
2025-09-04 10:37:47,232 - WARNING - Fallo conexión con mssql+pyodbc://sa:123@localhost/SQLEXPRESS/Prueba_Sep?driver=ODBC+Driver+17+for+SQL+Server: (pyodbc.InterfaceError) ('28000', '[28000] [Microsoft][ODBC Driver 17 for SQL Server][SQL Server]Login failed for user \'sa\'. (18456) (SQLDriverConnect); [28000] [Microsoft][ODBC Driver 17 for SQL Server][SQL Server]Cannot open database "SQLEXPRESS/Prueba_Sep" requested by the login. The login failed. (4060); [28000] [Microsoft][ODBC Driver 17 for SQL Server][SQL Server]Login failed for user \'sa\'. (18456); [28000] [Microsoft][ODBC Driver 17 for SQL Server][SQL Server]Cannot open database "SQLEXPRESS/Prueba_Sep" requested by the login. The login failed. (4060)')
(Background on this error at: https://sqlalche.me/e/20/rvf5)
